Workbook

Sheet USO ANUAL
B1: Utilização anual HPLC (dias em uso)
B4: Janeiro | I4: Fevereiro | P4: Março | W4: Abril | AD4: Maio | AK4: Junho | AR4: Julho | AY4: Agosto | BF4: Setembro | BM4: Outubro | BT4: Novembro | CA4: Dezembro
B5: Estatística do mês | I5: Estatística do mês | P5: Estatística do mês | W5: Estatística do mês | AD5: Estatística do mês | AK5: Estatística do mês | AR5: Estatística do mês | AY5: Estatística do mês | BF5: Estatística do mês | BM5: Estatística do mês | BT5: Estatística do mês | CA5: Estatística do mês
C6: HPLC.0034 | D6: HPLC.0035 | E6: HPLC.0036 | F6: HPLC.0037 | G6: HPLC.0045 | H6: HPLC.0050 | J6: HPLC.0034 | K6: HPLC.0035 | L6: HPLC.0036 | M6: HPLC.0037 | N6: HPLC.0045 | O6: HPLC.0050 | Q6: HPLC.0034 | R6: HPLC.0035 | S6: HPLC.0036 | T6: HPLC.0037 | U6: HPLC.0045 | V6: HPLC.0050 | X6: HPLC.0034 | Y6: HPLC.0035 | Z6: HPLC.0036 | AA6: HPLC.0037 | AB6: HPLC.0045 | AC6: HPLC.0050 | AE6: HPLC.0034 | AF6: HPLC.0035 | AG6: HPLC.0036 | AH6: HPLC.0037 | AI6: HPLC.0045 | AJ6: HPLC.0050 | AL6: HPLC.0034 | AM6: HPLC.0035 | AN6: HPLC.0036 | AO6: HPLC.0037 | AP6: HPLC.0045 | AQ6: HPLC.0050 | AS6: HPLC.0034 | AT6: HPLC.0035 | AU6: HPLC.0036 | AV6: HPLC.0037 | AW6: HPLC.0045 | AX6: HPLC.0050 | AZ6: HPLC.0034 | BA6: HPLC.0035 | BB6: HPLC.0036 | BC6: HPLC.0037 | BD6: HPLC.0045 | BE6: HPLC.0050 | BG6: HPLC.0034 | BH6: HPLC.0035 | BI6: HPLC.0036 | BJ6: HPLC.0037 | BK6: HPLC.0045 | BL6: HPLC.0050 | BN6: HPLC.0034 | BO6: HPLC.0035 | BP6: HPLC.0036 | BQ6: HPLC.0037 | BR6: HPLC.0045 | BS6: HPLC.0050 | BU6: HPLC.0034 | BV6: HPLC.0035 | BW6: HPLC.0036 | BX6: HPLC.0037 | BY6: HPLC.0045 | BZ6: HPLC.0050 | CB6: HPLC.0034 | CC6: HPLC.0035 | CD6: HPLC.0036 | CE6: HPLC.0037 | CF6: HPLC.0045 | CG6: HPLC.0050
B7: Em uso (1º turno) | C7: =COUNTIF(MP_Jan.20!$F$7:$CT$7,MP_Jan.20!$G36) -> 3 | D7: =COUNTIF(MP_Jan.20!$F$8:$CT$8,MP_Jan.20!$G36) -> 8 | E7: =COUNTIF(MP_Jan.20!$F$9:$CT$9,MP_Jan.20!$G36) -> 5 | F7: =COUNTIF(MP_Jan.20!$F$10:$CT$10,MP_Jan.20!$G36) -> 7 | G7: =COUNTIF(MP_Jan.20!$F$11:$CT$11,MP_Jan.20!$G36) -> 0 | H7: =COUNTIF(MP_Jan.20!$F$12:$CT$12,MP_Jan.20!$G36) -> 0 | I7: Em uso (1º turno) | J7: =COUNTIF(MP_Fev.20!$F$7:$CN$7,MP_Fev.20!$G36) -> 0 | K7: =COUNTIF(MP_Fev.20!$F$8:$CN$8,MP_Fev.20!$G36) -> 0 | L7: =COUNTIF(MP_Fev.20!$F$9:$CN$9,MP_Fev.20!$G36) -> 0 | M7: =COUNTIF(MP_Fev.20!$F$10:$CN$10,MP_Fev.20!$G36) -> 0 | N7: =COUNTIF(MP_Fev.20!$F$11:$CN$11,MP_Fev.20!$G36) -> 0 | O7: =COUNTIF(MP_Fev.20!$F$12:$CN$12,MP_Fev.20!$G36) -> 0 | P7: Em uso (1º turno) | Q7: =COUNTIF(MP_Mar.20!$F$7:$CT$7,MP_Mar.20!$G36) -> 0 | R7: =COUNTIF(MP_Mar.20!$F$8:$CT$8,MP_Mar.20!$G36) -> 0 | S7: =COUNTIF(MP_Mar.20!$F$9:$CT$9,MP_Mar.20!$G36) -> 0 | T7: =COUNTIF(MP_Mar.20!$F$10:$CT$10,MP_Mar.20!$G36) -> 0 | U7: =COUNTIF(MP_Mar.20!$F$11:$CT$11,MP_Mar.20!$G36) -> 0 | V7: =COUNTIF(MP_Mar.20!$F$12:$CT$12,MP_Mar.20!$G36) -> 0 | W7: Em uso (1º turno) | X7: =COUNTIF(MP_Abr.20!$F$7:$CQ$7,MP_Abr.20!$G36) -> 0 | Y7: =COUNTIF(MP_Abr.20!$F$8:$CQ$8,MP_Abr.20!$G36) -> 0 | Z7: =COUNTIF(MP_Abr.20!$F$9:$CQ$9,MP_Abr.20!$G36) -> 0 | AA7: =COUNTIF(MP_Abr.20!$F$10:$CQ$10,MP_Abr.20!$G36) -> 0 | AB7: =COUNTIF(MP_Abr.20!$F$11:$CQ$11,MP_Abr.20!$G36) -> 0 | AC7: =COUNTIF(MP_Abr.20!$F$12:$CQ$12,MP_Abr.20!$G36) -> 0 | AD7: Em uso (1º turno) | AE7: =COUNTIF(MP_Mai.20!$F$7:$CT$7,MP_Mai.20!$G36) -> 0 | AF7: =COUNTIF(MP_Mai.20!$F$8:$CT$8,MP_Mai.20!$G36) -> 0 | AG7: =COUNTIF(MP_Mai.20!$F$9:$CT$9,MP_Mai.20!$G36) -> 0 | AH7: =COUNTIF(MP_Mai.20!$F$10:$CT$10,MP_Mai.20!$G36) -> 0 | AI7: =COUNTIF(MP_Mai.20!$F$11:$CT$11,MP_Mai.20!$G36) -> 0 | AJ7: =COUNTIF(MP_Mai.20!$F$12:$CT$12,MP_Mai.20!$G36) -> 0 | AK7: Em uso (1º turno) | AL7: =COUNTIF(MP_Jun.20!$F$7:$CQ$7,MP_Jun.20!$G36) -> 0 | AM7: =COUNTIF(MP_Jun.20!$F$8:$CQ$8,MP_Jun.20!$G36) -> 0 | AN7: =COUNTIF(MP_Jun.20!$F$9:$CQ$9,MP_Jun.20!$G36) -> 0 | AO7: =COUNTIF(MP_Jun.20!$F$10:$CQ$10,MP_Jun.20!$G36) -> 0 | AP7: =COUNTIF(MP_Jun.20!$F$11:$CQ$11,MP_Jun.20!$G36) -> 0 | AQ7: =COUNTIF(MP_Jun.20!$F$12:$CQ$12,MP_Jun.20!$G36) -> 0 | AR7: Em uso (1º turno) | AS7: =COUNTIF(MP_Jul.20!$F$7:$CT$7,MP_Jul.20!$G36) -> 0 | AT7: =COUNTIF(MP_Jul.20!$F$8:$CT$8,MP_Jul.20!$G36) -> 0 | AU7: =COUNTIF(MP_Jul.20!$F$9:$CT$9,MP_Jul.20!$G36) -> 0 | AV7: =COUNTIF(MP_Jul.20!$F$10:$CT$10,MP_Jul.20!$G36) -> 0 | AW7: =COUNTIF(MP_Jul.20!$F$11:$CT$11,MP_Jul.20!$G36) -> 0 | AX7: =COUNTIF(MP_Jul.20!$F$12:$CT$12,MP_Jul.20!$G36) -> 0 | AY7: Em uso (1º turno) | AZ7: =COUNTIF(MP_Ago.20!$F$7:$CT$7,MP_Ago.20!$G36) -> 0 | BA7: =COUNTIF(MP_Ago.20!$F$8:$CT$8,MP_Ago.20!$G36) -> 0 | BB7: =COUNTIF(MP_Ago.20!$F$9:$CT$9,MP_Ago.20!$G36) -> 0 | BC7: =COUNTIF(MP_Ago.20!$F$10:$CT$10,MP_Ago.20!$G36) -> 0 | BD7: =COUNTIF(MP_Ago.20!$F$11:$CT$11,MP_Ago.20!$G36) -> 0 | BE7: =COUNTIF(MP_Ago.20!$F$12:$CT$12,MP_Ago.20!$G36) -> 0 | BF7: Em uso (1º turno) | BG7: =COUNTIF(MP_Set.20!$F$7:$CQ$7,MP_Set.20!$G36) -> 0 | BH7: =COUNTIF(MP_Set.20!$F$8:$CQ$8,MP_Set.20!$G36) -> 0 | BI7: =COUNTIF(MP_Set.20!$F$9:$CQ$9,MP_Set.20!$G36) -> 0 | BJ7: =COUNTIF(MP_Set.20!$F$10:$CQ$10,MP_Set.20!$G36) -> 0 | BK7: =COUNTIF(MP_Set.20!$F$11:$CQ$11,MP_Set.20!$G36) -> 0 | BL7: =COUNTIF(MP_Set.20!$F$12:$CQ$12,MP_Set.20!$G36) -> 0 | BM7: Em uso (1º turno) | BN7: =COUNTIF(MP_Out.20!$F$7:$CT$7,MP_Out.20!$G36) -> 0 | BO7: =COUNTIF(MP_Out.20!$F$8:$CT$8,MP_Out.20!$G36) -> 0 | BP7: =COUNTIF(MP_Out.20!$F$9:$CT$9,MP_Out.20!$G36) -> 0 | BQ7: =COUNTIF(MP_Out.20!$F$10:$CT$10,MP_Out.20!$G36) -> 0 | BR7: =COUNTIF(MP_Out.20!$F$11:$CT$11,MP_Out.20!$G36) -> 0 | BS7: =COUNTIF(MP_Out.20!$F$12:$CT$12,MP_Out.20!$G36) -> 0 | BT7: Em uso (1º turno) | BU7: =COUNTIF(MP_Nov.20!$F$7:$CQ$7,MP_Nov.20!$G36) -> 0 | BV7: =COUNTIF(MP_Nov.20!$F$8:$CQ$8,MP_Nov.20!$G36) -> 0 | BW7: =COUNTIF(MP_Nov.20!$F$9:$CQ$9,MP_Nov.20!$G36) -> 0 | BX7: =COUNTIF(MP_Nov.20!$F$10:$CQ$10,MP_Nov.20!$G36) -> 0 | BY7: =COUNTIF(MP_Nov.20!$F$11:$CQ$11,MP_Nov.20!$G36) -> 0 | BZ7: =COUNTIF(MP_Nov.20!$F$12:$CQ$12,MP_Nov.20!$G36) -> 0 | CA7: Em uso (1º turno) | CB7: =COUNTIF(MP_Dez.20!$F$7:$CT$7,MP_Dez.20!$G36) -> 0 | CC7: =COUNTIF(MP_Dez.20!$F$8:$CT$8,MP_Dez.20!$G36) -> 0 | CD7: =COUNTIF(MP_Dez.20!$F$9:$CT$9,MP_Dez.20!$G36) -> 0 | CE7: =COUNTIF(MP_Dez.20!$F$10:$CT$10,MP_Dez.20!$G36) -> 0 | CF7: =COUNTIF(MP_Dez.20!$F$11:$CT$11,MP_Dez.20!$G36) -> 0 | CG7: =COUNTIF(MP_Dez.20!$F$12:$CT$12,MP_Dez.20!$G36) -> 0
B8: Em uso (2º turno) | C8: =COUNTIF(MP_Jan.20!$F$7:$CT$7,MP_Jan.20!$G37) -> 10 | D8: =COUNTIF(MP_Jan.20!$F$8:$CT$8,MP_Jan.20!$G37) -> 5 | E8: =COUNTIF(MP_Jan.20!$F$9:$CT$9,MP_Jan.20!$G37) -> 6 | F8: =COUNTIF(MP_Jan.20!$F$10:$CT$10,MP_Jan.20!$G37) -> 0 | G8: =COUNTIF(MP_Jan.20!$F$11:$CT$11,MP_Jan.20!$G37) -> 10 | H8: =COUNTIF(MP_Jan.20!$F$12:$CT$12,MP_Jan.20!$G37) -> 0 | I8: Em uso (2º turno) | J8: =COUNTIF(MP_Fev.20!$F$7:$CN$7,MP_Fev.20!$G37) -> 0 | K8: =COUNTIF(MP_Fev.20!$F$8:$CN$8,MP_Fev.20!$G37) -> 0 | L8: =COUNTIF(MP_Fev.20!$F$9:$CN$9,MP_Fev.20!$G37) -> 0 | M8: =COUNTIF(MP_Fev.20!$F$10:$CN$10,MP_Fev.20!$G37) -> 0 | N8: =COUNTIF(MP_Fev.20!$F$11:$CN$11,MP_Fev.20!$G37) -> 0 | O8: =COUNTIF(MP_Fev.20!$F$12:$CN$12,MP_Fev.20!$G37) -> 0 | P8: Em uso (2º turno) | Q8: =COUNTIF(MP_Mar.20!$F$7:$CT$7,MP_Mar.20!$G37) -> 0 | R8: =COUNTIF(MP_Mar.20!$F$8:$CT$8,MP_Mar.20!$G37) -> 0 | S8: =COUNTIF(MP_Mar.20!$F$9:$CT$9,MP_Mar.20!$G37) -> 0 | T8: =COUNTIF(MP_Mar.20!$F$10:$CT$10,MP_Mar.20!$G37) -> 0 | U8: =COUNTIF(MP_Mar.20!$F$11:$CT$11,MP_Mar.20!$G37) -> 0 | V8: =COUNTIF(MP_Mar.20!$F$12:$CT$12,MP_Mar.20!$G37) -> 0 | W8: Em uso (2º turno) | X8: =COUNTIF(MP_Abr.20!$F$7:$CQ$7,MP_Abr.20!$G37) -> 0 | Y8: =COUNTIF(MP_Abr.20!$F$8:$CQ$8,MP_Abr.20!$G37) -> 0 | Z8: =COUNTIF(MP_Abr.20!$F$9:$CQ$9,MP_Abr.20!$G37) -> 0 | AA8: =COUNTIF(MP_Abr.20!$F$10:$CQ$10,MP_Abr.20!$G37) -> 0 | AB8: =COUNTIF(MP_Abr.20!$F$11:$CQ$11,MP_Abr.20!$G37) -> 0 | AC8: =COUNTIF(MP_Abr.20!$F$12:$CQ$12,MP_Abr.20!$G37) -> 0 | AD8: Em uso (2º turno) | AE8: =COUNTIF(MP_Mai.20!$F$7:$CT$7,MP_Mai.20!$G37) -> 0 | AF8: =COUNTIF(MP_Mai.20!$F$8:$CT$8,MP_Mai.20!$G37) -> 0 | AG8: =COUNTIF(MP_Mai.20!$F$9:$CT$9,MP_Mai.20!$G37) -> 0 | AH8: =COUNTIF(MP_Mai.20!$F$10:$CT$10,MP_Mai.20!$G37) -> 0 | AI8: =COUNTIF(MP_Mai.20!$F$11:$CT$11,MP_Mai.20!$G37) -> 0 | AJ8: =COUNTIF(MP_Mai.20!$F$12:$CT$12,MP_Mai.20!$G37) -> 0 | AK8: Em uso (2º turno) | AL8: =COUNTIF(MP_Jun.20!$F$7:$CQ$7,MP_Jun.20!$G37) -> 0 | AM8: =COUNTIF(MP_Jun.20!$F$8:$CQ$8,MP_Jun.20!$G37) -> 0 | AN8: =COUNTIF(MP_Jun.20!$F$9:$CQ$9,MP_Jun.20!$G37) -> 0 | AO8: =COUNTIF(MP_Jun.20!$F$10:$CQ$10,MP_Jun.20!$G37) -> 0 | AP8: =COUNTIF(MP_Jun.20!$F$11:$CQ$11,MP_Jun.20!$G37) -> 0 | AQ8: =COUNTIF(MP_Jun.20!$F$12:$CQ$12,MP_Jun.20!$G37) -> 0 | AR8: Em uso (2º turno) | AS8: =COUNTIF(MP_Jul.20!$F$7:$CT$7,MP_Jul.20!$G37) -> 0 | AT8: =COUNTIF(MP_Jul.20!$F$8:$CT$8,MP_Jul.20!$G37) -> 0 | AU8: =COUNTIF(MP_Jul.20!$F$9:$CT$9,MP_Jul.20!$G37) -> 0 | AV8: =COUNTIF(MP_Jul.20!$F$10:$CT$10,MP_Jul.20!$G37) -> 0 | AW8: =COUNTIF(MP_Jul.20!$F$11:$CT$11,MP_Jul.20!$G37) -> 0 | AX8: =COUNTIF(MP_Jul.20!$F$12:$CT$12,MP_Jul.20!$G37) -> 0 | AY8: Em uso (2º turno) | AZ8: =COUNTIF(MP_Ago.20!$F$7:$CT$7,MP_Ago.20!$G37) -> 0 | BA8: =COUNTIF(MP_Ago.20!$F$8:$CT$8,MP_Ago.20!$G37) -> 0 | BB8: =COUNTIF(MP_Ago.20!$F$9:$CT$9,MP_Ago.20!$G37) -> 0 | BC8: =COUNTIF(MP_Ago.20!$F$10:$CT$10,MP_Ago.20!$G37) -> 0 | BD8: =COUNTIF(MP_Ago.20!$F$11:$CT$11,MP_Ago.20!$G37) -> 0 | BE8: =COUNTIF(MP_Ago.20!$F$12:$CT$12,MP_Ago.20!$G37) -> 0 | BF8: Em uso (2º turno) | BG8: =COUNTIF(MP_Set.20!$F$7:$CQ$7,MP_Set.20!$G37) -> 0 | BH8: =COUNTIF(MP_Set.20!$F$8:$CQ$8,MP_Set.20!$G37) -> 0 | BI8: =COUNTIF(MP_Set.20!$F$9:$CQ$9,MP_Set.20!$G37) -> 0 | BJ8: =COUNTIF(MP_Set.20!$F$10:$CQ$10,MP_Set.20!$G37) -> 0 | BK8: =COUNTIF(MP_Set.20!$F$11:$CQ$11,MP_Set.20!$G37) -> 0 | BL8: =COUNTIF(MP_Set.20!$F$12:$CQ$12,MP_Set.20!$G37) -> 0 | BM8: Em uso (2º turno) | BN8: =COUNTIF(MP_Out.20!$F$7:$CT$7,MP_Out.20!$G37) -> 0 | BO8: =COUNTIF(MP_Out.20!$F$8:$CT$8,MP_Out.20!$G37) -> 0 | BP8: =COUNTIF(MP_Out.20!$F$9:$CT$9,MP_Out.20!$G37) -> 0 | BQ8: =COUNTIF(MP_Out.20!$F$10:$CT$10,MP_Out.20!$G37) -> 0 | BR8: =COUNTIF(MP_Out.20!$F$11:$CT$11,MP_Out.20!$G37) -> 0 | BS8: =COUNTIF(MP_Out.20!$F$12:$CT$12,MP_Out.20!$G37) -> 0 | BT8: Em uso (2º turno) | BU8: =COUNTIF(MP_Nov.20!$F$7:$CQ$7,MP_Nov.20!$G37) -> 0 | BV8: =COUNTIF(MP_Nov.20!$F$8:$CQ$8,MP_Nov.20!$G37) -> 0 | BW8: =COUNTIF(MP_Nov.20!$F$9:$CQ$9,MP_Nov.20!$G37) -> 0 | BX8: =COUNTIF(MP_Nov.20!$F$10:$CQ$10,MP_Nov.20!$G37) -> 0 | BY8: =COUNTIF(MP_Nov.20!$F$11:$CQ$11,MP_Nov.20!$G37) -> 0 | BZ8: =COUNTIF(MP_Nov.20!$F$12:$CQ$12,MP_Nov.20!$G37) -> 0 | CA8: Em uso (2º turno) | CB8: =COUNTIF(MP_Dez.20!$F$7:$CT$7,MP_Dez.20!$G37) -> 0 | CC8: =COUNTIF(MP_Dez.20!$F$8:$CT$8,MP_Dez.20!$G37) -> 0 | CD8: =COUNTIF(MP_Dez.20!$F$9:$CT$9,MP_Dez.20!$G37) -> 0 | CE8: =COUNTIF(MP_Dez.20!$F$10:$CT$10,MP_Dez.20!$G37) -> 0 | CF8: =COUNTIF(MP_Dez.20!$F$11:$CT$11,MP_Dez.20!$G37) -> 0 | CG8: =COUNTIF(MP_Dez.20!$F$12:$CT$12,MP_Dez.20!$G37) -> 0
B9: Qualificação | C9: =COUNTIF(MP_Jan.20!$F$7:$CT$7,MP_Jan.20!$G38) -> 0 | D9: =COUNTIF(MP_Jan.20!$F$8:$CT$8,MP_Jan.20!$G38) -> 0 | E9: =COUNTIF(MP_Jan.20!$F$9:$CT$9,MP_Jan.20!$G38) -> 0 | F9: =COUNTIF(MP_Jan.20!$F$10:$CT$10,MP_Jan.20!$G38) -> 0 | G9: =COUNTIF(MP_Jan.20!$F$11:$CT$11,MP_Jan.20!$G38) -> 0 | H9: =COUNTIF(MP_Jan.20!$F$12:$CT$12,MP_Jan.20!$G38) -> 0 | I9: Qualificação | J9: =COUNTIF(MP_Fev.20!$F$7:$CN$7,MP_Fev.20!$G38) -> 0 | K9: =COUNTIF(MP_Fev.20!$F$8:$CN$8,MP_Fev.20!$G38) -> 0 | L9: =COUNTIF(MP_Fev.20!$F$9:$CN$9,MP_Fev.20!$G38) -> 0 | M9: =COUNTIF(MP_Fev.20!$F$10:$CN$10,MP_Fev.20!$G38) -> 0 | N9: =COUNTIF(MP_Fev.20!$F$11:$CN$11,MP_Fev.20!$G38) -> 0 | O9: =COUNTIF(MP_Fev.20!$F$12:$CN$12,MP_Fev.20!$G38) -> 0 | P9: Qualificação | Q9: =COUNTIF(MP_Mar.20!$F$7:$CT$7,MP_Mar.20!$G38) -> 0 | R9: =COUNTIF(MP_Mar.20!$F$8:$CT$8,MP_Mar.20!$G38) -> 0 | S9: =COUNTIF(MP_Mar.20!$F$9:$CT$9,MP_Mar.20!$G38) -> 0 | T9: =COUNTIF(MP_Mar.20!$F$10:$CT$10,MP_Mar.20!$G38) -> 0 | U9: =COUNTIF(MP_Mar.20!$F$11:$CT$11,MP_Mar.20!$G38) -> 0 | V9: =COUNTIF(MP_Mar.20!$F$12:$CT$12,MP_Mar.20!$G38) -> 0 | W9: Qualificação | X9: =COUNTIF(MP_Abr.20!$F$7:$CQ$7,MP_Abr.20!$G38) -> 0 | Y9: =COUNTIF(MP_Abr.20!$F$8:$CQ$8,MP_Abr.20!$G38) -> 0 | Z9: =COUNTIF(MP_Abr.20!$F$9:$CQ$9,MP_Abr.20!$G38) -> 0 | AA9: =COUNTIF(MP_Abr.20!$F$10:$CQ$10,MP_Abr.20!$G38) -> 0 | AB9: =COUNTIF(MP_Abr.20!$F$11:$CQ$11,MP_Abr.20!$G38) -> 0 | AC9: =COUNTIF(MP_Abr.20!$F$12:$CQ$12,MP_Abr.20!$G38) -> 0 | AD9: Qualificação | AE9: =COUNTIF(MP_Mai.20!$F$7:$CT$7,MP_Mai.20!$G38) -> 0 | AF9: =COUNTIF(MP_Mai.20!$F$8:$CT$8,MP_Mai.20!$G38) -> 0 | AG9: =COUNTIF(MP_Mai.20!$F$9:$CT$9,MP_Mai.20!$G38) -> 0 | AH9: =COUNTIF(MP_Mai.20!$F$10:$CT$10,MP_Mai.20!$G38) -> 0 | AI9: =COUNTIF(MP_Mai.20!$F$11:$CT$11,MP_Mai.20!$G38) -> 0 | AJ9: =COUNTIF(MP_Mai.20!$F$12:$CT$12,MP_Mai.20!$G38) -> 0 | AK9: Qualificação | AL9: =COUNTIF(MP_Jun.20!$F$7:$CQ$7,MP_Jun.20!$G38) -> 0 | AM9: =COUNTIF(MP_Jun.20!$F$8:$CQ$8,MP_Jun.20!$G38) -> 0 | AN9: =COUNTIF(MP_Jun.20!$F$9:$CQ$9,MP_Jun.20!$G38) -> 0 | AO9: =COUNTIF(MP_Jun.20!$F$10:$CQ$10,MP_Jun.20!$G38) -> 0 | AP9: =COUNTIF(MP_Jun.20!$F$11:$CQ$11,MP_Jun.20!$G38) -> 0 | AQ9: =COUNTIF(MP_Jun.20!$F$12:$CQ$12,MP_Jun.20!$G38) -> 0 | AR9: Qualificação | AS9: =COUNTIF(MP_Jul.20!$F$7:$CT$7,MP_Jul.20!$G38) -> 0 | AT9: =COUNTIF(MP_Jul.20!$F$8:$CT$8,MP_Jul.20!$G38) -> 0 | AU9: =COUNTIF(MP_Jul.20!$F$9:$CT$9,MP_Jul.20!$G38) -> 0 | AV9: =COUNTIF(MP_Jul.20!$F$10:$CT$10,MP_Jul.20!$G38) -> 0 | AW9: =COUNTIF(MP_Jul.20!$F$11:$CT$11,MP_Jul.20!$G38) -> 0 | AX9: =COUNTIF(MP_Jul.20!$F$12:$CT$12,MP_Jul.20!$G38) -> 0 | AY9: Qualificação | AZ9: =COUNTIF(MP_Ago.20!$F$7:$CT$7,MP_Ago.20!$G38) -> 0 | BA9: =COUNTIF(MP_Ago.20!$F$8:$CT$8,MP_Ago.20!$G38) -> 0 | BB9: =COUNTIF(MP_Ago.20!$F$9:$CT$9,MP_Ago.20!$G38) -> 0 | BC9: =COUNTIF(MP_Ago.20!$F$10:$CT$10,MP_Ago.20!$G38) -> 0 | BD9: =COUNTIF(MP_Ago.20!$F$11:$CT$11,MP_Ago.20!$G38) -> 0 | BE9: =COUNTIF(MP_Ago.20!$F$12:$CT$12,MP_Ago.20!$G38) -> 0 | BF9: Qualificação | BG9: =COUNTIF(MP_Set.20!$F$7:$CQ$7,MP_Set.20!$G38) -> 0 | BH9: =COUNTIF(MP_Set.20!$F$8:$CQ$8,MP_Set.20!$G38) -> 0 | BI9: =COUNTIF(MP_Set.20!$F$9:$CQ$9,MP_Set.20!$G38) -> 0 | BJ9: =COUNTIF(MP_Set.20!$F$10:$CQ$10,MP_Set.20!$G38) -> 0 | BK9: =COUNTIF(MP_Set.20!$F$11:$CQ$11,MP_Set.20!$G38) -> 0 | BL9: =COUNTIF(MP_Set.20!$F$12:$CQ$12,MP_Set.20!$G38) -> 0 | BM9: Qualificação | BN9: =COUNTIF(MP_Out.20!$F$7:$CT$7,MP_Out.20!$G38) -> 0 | BO9: =COUNTIF(MP_Out.20!$F$8:$CT$8,MP_Out.20!$G38) -> 0 | BP9: =COUNTIF(MP_Out.20!$F$9:$CT$9,MP_Out.20!$G38) -> 0 | BQ9: =COUNTIF(MP_Out.20!$F$10:$CT$10,MP_Out.20!$G38) -> 0 | BR9: =COUNTIF(MP_Out.20!$F$11:$CT$11,MP_Out.20!$G38) -> 0 | BS9: =COUNTIF(MP_Out.20!$F$12:$CT$12,MP_Out.20!$G38) -> 0 | BT9: Qualificação | BU9: =COUNTIF(MP_Nov.20!$F$7:$CQ$7,MP_Nov.20!$G38) -> 0 | BV9: =COUNTIF(MP_Nov.20!$F$8:$CQ$8,MP_Nov.20!$G38) -> 0 | BW9: =COUNTIF(MP_Nov.20!$F$9:$CQ$9,MP_Nov.20!$G38) -> 0 | BX9: =COUNTIF(MP_Nov.20!$F$10:$CQ$10,MP_Nov.20!$G38) -> 0 | BY9: =COUNTIF(MP_Nov.20!$F$11:$CQ$11,MP_Nov.20!$G38) -> 0 | BZ9: =COUNTIF(MP_Nov.20!$F$12:$CQ$12,MP_Nov.20!$G38) -> 0 | CA9: Qualificação | CB9: =COUNTIF(MP_Dez.20!$F$7:$CT$7,MP_Dez.20!$G38) -> 0 | CC9: =COUNTIF(MP_Dez.20!$F$8:$CT$8,MP_Dez.20!$G38) -> 0 | CD9: =COUNTIF(MP_Dez.20!$F$9:$CT$9,MP_Dez.20!$G38) -> 0 | CE9: =COUNTIF(MP_Dez.20!$F$10:$CT$10,MP_Dez.20!$G38) -> 0 | CF9: =COUNTIF(MP_Dez.20!$F$11:$CT$11,MP_Dez.20!$G38) -> 0 | CG9: =COUNTIF(MP_Dez.20!$F$12:$CT$12,MP_Dez.20!$G38) -> 0
B10: Empréstimo - Desenho analítico / IVIV | C10: =COUNTIF(MP_Jan.20!$F$7:$CT$7,MP_Jan.20!$G39) -> 0 | D10: =COUNTIF(MP_Jan.20!$F$8:$CT$8,MP_Jan.20!$G39) -> 0 | E10: =COUNTIF(MP_Jan.20!$F$9:$CT$9,MP_Jan.20!$G39) -> 0 | F10: =COUNTIF(MP_Jan.20!$F$10:$CT$10,MP_Jan.20!$G39) -> 0 | G10: =COUNTIF(MP_Jan.20!$F$11:$CT$11,MP_Jan.20!$G39) -> 0 | H10: =COUNTIF(MP_Jan.20!$F$12:$CT$12,MP_Jan.20!$G39) -> 0 | I10: Empréstimo - Desenho analítico / IVIV | J10: =COUNTIF(MP_Fev.20!$F$7:$CN$7,MP_Fev.20!$G39) -> 0 | K10: =COUNTIF(MP_Fev.20!$F$8:$CN$8,MP_Fev.20!$G39) -> 0 | L10: =COUNTIF(MP_Fev.20!$F$9:$CN$9,MP_Fev.20!$G39) -> 0 | M10: =COUNTIF(MP_Fev.20!$F$10:$CN$10,MP_Fev.20!$G39) -> 0 | N10: =COUNTIF(MP_Fev.20!$F$11:$CN$11,MP_Fev.20!$G39) -> 0 | O10: =COUNTIF(MP_Fev.20!$F$12:$CN$12,MP_Fev.20!$G39) -> 0 | P10: Empréstimo - Desenho analítico / IVIV | Q10: =COUNTIF(MP_Mar.20!$F$7:$CT$7,MP_Mar.20!$G39) -> 0 | R10: =COUNTIF(MP_Mar.20!$F$8:$CT$8,MP_Mar.20!$G39) -> 0 | S10: =COUNTIF(MP_Mar.20!$F$9:$CT$9,MP_Mar.20!$G39) -> 0 | T10: =COUNTIF(MP_Mar.20!$F$10:$CT$10,MP_Mar.20!$G39) -> 0 | U10: =COUNTIF(MP_Mar.20!$F$11:$CT$11,MP_Mar.20!$G39) -> 0 | V10: =COUNTIF(MP_Mar.20!$F$12:$CT$12,MP_Mar.20!$G39) -> 0 | W10: Empréstimo - Desenho analítico / IVIV | X10: =COUNTIF(MP_Abr.20!$F$7:$CQ$7,MP_Abr.20!$G39) -> 0 | Y10: =COUNTIF(MP_Abr.20!$F$8:$CQ$8,MP_Abr.20!$G39) -> 0 | Z10: =COUNTIF(MP_Abr.20!$F$9:$CQ$9,MP_Abr.20!$G39) -> 0 | AA10: =COUNTIF(MP_Abr.20!$F$10:$CQ$10,MP_Abr.20!$G39) -> 0 | AB10: =COUNTIF(MP_Abr.20!$F$11:$CQ$11,MP_Abr.20!$G39) -> 0 | AC10: =COUNTIF(MP_Abr.20!$F$12:$CQ$12,MP_Abr.20!$G39) -> 0 | AD10: Empréstimo - Desenho analítico / IVIV | AE10: =COUNTIF(MP_Mai.20!$F$7:$CT$7,MP_Mai.20!$G39) -> 0 | AF10: =COUNTIF(MP_Mai.20!$F$8:$CT$8,MP_Mai.20!$G39) -> 0 | AG10: =COUNTIF(MP_Mai.20!$F$9:$CT$9,MP_Mai.20!$G39) -> 0 | AH10: =COUNTIF(MP_Mai.20!$F$10:$CT$10,MP_Mai.20!$G39) -> 0 | AI10: =COUNTIF(MP_Mai.20!$F$11:$CT$11,MP_Mai.20!$G39) -> 0 | AJ10: =COUNTIF(MP_Mai.20!$F$12:$CT$12,MP_Mai.20!$G39) -> 0 | AK10: Empréstimo - Desenho analítico / IVIV | AL10: =COUNTIF(MP_Jun.20!$F$7:$CQ$7,MP_Jun.20!$G39) -> 0 | AM10: =COUNTIF(MP_Jun.20!$F$8:$CQ$8,MP_Jun.20!$G39) -> 0 | AN10: =COUNTIF(MP_Jun.20!$F$9:$CQ$9,MP_Jun.20!$G39) -> 0 | AO10: =COUNTIF(MP_Jun.20!$F$10:$CQ$10,MP_Jun.20!$G39) -> 0 | AP10: =COUNTIF(MP_Jun.20!$F$11:$CQ$11,MP_Jun.20!$G39) -> 0 | AQ10: =COUNTIF(MP_Jun.20!$F$12:$CQ$12,MP_Jun.20!$G39) -> 0 | AR10: Empréstimo - Desenho analítico / IVIV | AS10: =COUNTIF(MP_Jul.20!$F$7:$CT$7,MP_Jul.20!$G39) -> 0 | AT10: =COUNTIF(MP_Jul.20!$F$8:$CT$8,MP_Jul.20!$G39) -> 0 | AU10: =COUNTIF(MP_Jul.20!$F$9:$CT$9,MP_Jul.20!$G39) -> 0 | AV10: =COUNTIF(MP_Jul.20!$F$10:$CT$10,MP_Jul.20!$G39) -> 0 | AW10: =COUNTIF(MP_Jul.20!$F$11:$CT$11,MP_Jul.20!$G39) -> 0 | AX10: =COUNTIF(MP_Jul.20!$F$12:$CT$12,MP_Jul.20!$G39) -> 0 | AY10: Empréstimo - Desenho analítico / IVIV | AZ10: =COUNTIF(MP_Ago.20!$F$7:$CT$7,MP_Ago.20!$G39) -> 0 | BA10: =COUNTIF(MP_Ago.20!$F$8:$CT$8,MP_Ago.20!$G39) -> 0 | BB10: =COUNTIF(MP_Ago.20!$F$9:$CT$9,MP_Ago.20!$G39) -> 0 | BC10: =COUNTIF(MP_Ago.20!$F$10:$CT$10,MP_Ago.20!$G39) -> 0 | BD10: =COUNTIF(MP_Ago.20!$F$11:$CT$11,MP_Ago.20!$G39) -> 0 | BE10: =COUNTIF(MP_Ago.20!$F$12:$CT$12,MP_Ago.20!$G39) -> 0 | BF10: Empréstimo - Desenho analítico / IVIV | BG10: =COUNTIF(MP_Set.20!$F$7:$CQ$7,MP_Set.20!$G39) -> 0 | BH10: =COUNTIF(MP_Set.20!$F$8:$CQ$8,MP_Set.20!$G39) -> 0 | BI10: =COUNTIF(MP_Set.20!$F$9:$CQ$9,MP_Set.20!$G39) -> 0 | BJ10: =COUNTIF(MP_Set.20!$F$10:$CQ$10,MP_Set.20!$G39) -> 0 | BK10: =COUNTIF(MP_Set.20!$F$11:$CQ$11,MP_Set.20!$G39) -> 0 | BL10: =COUNTIF(MP_Set.20!$F$12:$CQ$12,MP_Set.20!$G39) -> 0 | BM10: Empréstimo - Desenho analítico / IVIV | BN10: =COUNTIF(MP_Out.20!$F$7:$CT$7,MP_Out.20!$G39) -> 0 | BO10: =COUNTIF(MP_Out.20!$F$8:$CT$8,MP_Out.20!$G39) -> 0 | BP10: =COUNTIF(MP_Out.20!$F$9:$CT$9,MP_Out.20!$G39) -> 0 | BQ10: =COUNTIF(MP_Out.20!$F$10:$CT$10,MP_Out.20!$G39) -> 0 | BR10: =COUNTIF(MP_Out.20!$F$11:$CT$11,MP_Out.20!$G39) -> 0 | BS10: =COUNTIF(MP_Out.20!$F$12:$CT$12,MP_Out.20!$G39) -> 0 | BT10: Empréstimo - Desenho analítico / IVIV | BU10: =COUNTIF(MP_Nov.20!$F$7:$CQ$7,MP_Nov.20!$G39) -> 0 | BV10: =COUNTIF(MP_Nov.20!$F$8:$CQ$8,MP_Nov.20!$G39) -> 0 | BW10: =COUNTIF(MP_Nov.20!$F$9:$CQ$9,MP_Nov.20!$G39) -> 0 | BX10: =COUNTIF(MP_Nov.20!$F$10:$CQ$10,MP_Nov.20!$G39) -> 0 | BY10: =COUNTIF(MP_Nov.20!$F$11:$CQ$11,MP_Nov.20!$G39) -> 0 | BZ10: =COUNTIF(MP_Nov.20!$F$12:$CQ$12,MP_Nov.20!$G39) -> 0 | CA10: Empréstimo - Desenho analítico / IVIV | CB10: =COUNTIF(MP_Dez.20!$F$7:$CT$7,MP_Dez.20!$G39) -> 0 | CC10: =COUNTIF(MP_Dez.20!$F$8:$CT$8,MP_Dez.20!$G39) -> 0 | CD10: =COUNTIF(MP_Dez.20!$F$9:$CT$9,MP_Dez.20!$G39) -> 0 | CE10: =COUNTIF(MP_Dez.20!$F$10:$CT$10,MP_Dez.20!$G39) -> 0 | CF10: =COUNTIF(MP_Dez.20!$F$11:$CT$11,MP_Dez.20!$G39) -> 0 | CG10: =COUNTIF(MP_Dez.20!$F$12:$CT$12,MP_Dez.20!$G39) -> 0
B11: Empréstimo - Diss | C11: =COUNTIF(MP_Jan.20!$F$7:$CT$7,MP_Jan.20!$G40) -> 0 | D11: =COUNTIF(MP_Jan.20!$F$8:$CT$8,MP_Jan.20!$G40) -> 0 | E11: =COUNTIF(MP_Jan.20!$F$9:$CT$9,MP_Jan.20!$G40) -> 0 | F11: =COUNTIF(MP_Jan.20!$F$10:$CT$10,MP_Jan.20!$G40) -> 0 | G11: =COUNTIF(MP_Jan.20!$F$11:$CT$11,MP_Jan.20!$G40) -> 0 | H11: =COUNTIF(MP_Jan.20!$F$12:$CT$12,MP_Jan.20!$G40) -> 0 | I11: Empréstimo - Diss | J11: =COUNTIF(MP_Fev.20!$F$7:$CN$7,MP_Fev.20!$G40) -> 0 | K11: =COUNTIF(MP_Fev.20!$F$8:$CN$8,MP_Fev.20!$G40) -> 0 | L11: =COUNTIF(MP_Fev.20!$F$9:$CN$9,MP_Fev.20!$G40) -> 0 | M11: =COUNTIF(MP_Fev.20!$F$10:$CN$10,MP_Fev.20!$G40) -> 0 | N11: =COUNTIF(MP_Fev.20!$F$11:$CN$11,MP_Fev.20!$G40) -> 0 | O11: =COUNTIF(MP_Fev.20!$F$12:$CN$12,MP_Fev.20!$G40) -> 0 | P11: Empréstimo - Diss | Q11: =COUNTIF(MP_Mar.20!$F$7:$CT$7,MP_Mar.20!$G40) -> 0 | R11: =COUNTIF(MP_Mar.20!$F$8:$CT$8,MP_Mar.20!$G40) -> 0 | S11: =COUNTIF(MP_Mar.20!$F$9:$CT$9,MP_Mar.20!$G40) -> 0 | T11: =COUNTIF(MP_Mar.20!$F$10:$CT$10,MP_Mar.20!$G40) -> 0 | U11: =COUNTIF(MP_Mar.20!$F$11:$CT$11,MP_Mar.20!$G40) -> 0 | V11: =COUNTIF(MP_Mar.20!$F$12:$CT$12,MP_Mar.20!$G40) -> 0 | W11: Empréstimo - Diss | X11: =COUNTIF(MP_Abr.20!$F$7:$CQ$7,MP_Abr.20!$G40) -> 0 | Y11: =COUNTIF(MP_Abr.20!$F$8:$CQ$8,MP_Abr.20!$G40) -> 0 | Z11: =COUNTIF(MP_Abr.20!$F$9:$CQ$9,MP_Abr.20!$G40) -> 0 | AA11: =COUNTIF(MP_Abr.20!$F$10:$CQ$10,MP_Abr.20!$G40) -> 0 | AB11: =COUNTIF(MP_Abr.20!$F$11:$CQ$11,MP_Abr.20!$G40) -> 0 | AC11: =COUNTIF(MP_Abr.20!$F$12:$CQ$12,MP_Abr.20!$G40) -> 0 | AD11: Empréstimo - Diss | AE11: =COUNTIF(MP_Mai.20!$F$7:$CT$7,MP_Mai.20!$G40) -> 0 | AF11: =COUNTIF(MP_Mai.20!$F$8:$CT$8,MP_Mai.20!$G40) -> 0 | AG11: =COUNTIF(MP_Mai.20!$F$9:$CT$9,MP_Mai.20!$G40) -> 0 | AH11: =COUNTIF(MP_Mai.20!$F$10:$CT$10,MP_Mai.20!$G40) -> 0 | AI11: =COUNTIF(MP_Mai.20!$F$11:$CT$11,MP_Mai.20!$G40) -> 0 | AJ11: =COUNTIF(MP_Mai.20!$F$12:$CT$12,MP_Mai.20!$G40) -> 0 | AK11: Empréstimo - Diss | AL11: =COUNTIF(MP_Jun.20!$F$7:$CQ$7,MP_Jun.20!$G40) -> 0 | AM11: =COUNTIF(MP_Jun.20!$F$8:$CQ$8,MP_Jun.20!$G40) -> 0 | AN11: =COUNTIF(MP_Jun.20!$F$9:$CQ$9,MP_Jun.20!$G40) -> 0 | AO11: =COUNTIF(MP_Jun.20!$F$10:$CQ$10,MP_Jun.20!$G40) -> 0 | AP11: =COUNTIF(MP_Jun.20!$F$11:$CQ$11,MP_Jun.20!$G40) -> 0 | AQ11: =COUNTIF(MP_Jun.20!$F$12:$CQ$12,MP_Jun.20!$G40) -> 0 | AR11: Empréstimo - Diss | AS11: =COUNTIF(MP_Jul.20!$F$7:$CT$7,MP_Jul.20!$G40) -> 0 | AT11: =COUNTIF(MP_Jul.20!$F$8:$CT$8,MP_Jul.20!$G40) -> 0 | AU11: =COUNTIF(MP_Jul.20!$F$9:$CT$9,MP_Jul.20!$G40) -> 0 | AV11: =COUNTIF(MP_Jul.20!$F$10:$CT$10,MP_Jul.20!$G40) -> 0 | AW11: =COUNTIF(MP_Jul.20!$F$11:$CT$11,MP_Jul.20!$G40) -> 0 | AX11: =COUNTIF(MP_Jul.20!$F$12:$CT$12,MP_Jul.20!$G40) -> 0 | AY11: Empréstimo - Diss | AZ11: =COUNTIF(MP_Ago.20!$F$7:$CT$7,MP_Ago.20!$G40) -> 0 | BA11: =COUNTIF(MP_Ago.20!$F$8:$CT$8,MP_Ago.20!$G40) -> 0 | BB11: =COUNTIF(MP_Ago.20!$F$9:$CT$9,MP_Ago.20!$G40) -> 0 | BC11: =COUNTIF(MP_Ago.20!$F$10:$CT$10,MP_Ago.20!$G40) -> 0 | BD11: =COUNTIF(MP_Ago.20!$F$11:$CT$11,MP_Ago.20!$G40) -> 0 | BE11: =COUNTIF(MP_Ago.20!$F$12:$CT$12,MP_Ago.20!$G40) -> 0 | BF11: Empréstimo - Diss | BG11: =COUNTIF(MP_Set.20!$F$7:$CQ$7,MP_Set.20!$G40) -> 0 | BH11: =COUNTIF(MP_Set.20!$F$8:$CQ$8,MP_Set.20!$G40) -> 0 | BI11: =COUNTIF(MP_Set.20!$F$9:$CQ$9,MP_Set.20!$G40) -> 0 | BJ11: =COUNTIF(MP_Set.20!$F$10:$CQ$10,MP_Set.20!$G40) -> 0 | BK11: =COUNTIF(MP_Set.20!$F$11:$CQ$11,MP_Set.20!$G40) -> 0 | BL11: =COUNTIF(MP_Set.20!$F$12:$CQ$12,MP_Set.20!$G40) -> 0 | BM11: Empréstimo - Diss | BN11: =COUNTIF(MP_Out.20!$F$7:$CT$7,MP_Out.20!$G40) -> 0 | BO11: =COUNTIF(MP_Out.20!$F$8:$CT$8,MP_Out.20!$G40) -> 0 | BP11: =COUNTIF(MP_Out.20!$F$9:$CT$9,MP_Out.20!$G40) -> 0 | BQ11: =COUNTIF(MP_Out.20!$F$10:$CT$10,MP_Out.20!$G40) -> 0 | BR11: =COUNTIF(MP_Out.20!$F$11:$CT$11,MP_Out.20!$G40) -> 0 | BS11: =COUNTIF(MP_Out.20!$F$12:$CT$12,MP_Out.20!$G40) -> 0 | BT11: Empréstimo - Diss | BU11: =COUNTIF(MP_Nov.20!$F$7:$CQ$7,MP_Nov.20!$G40) -> 0 | BV11: =COUNTIF(MP_Nov.20!$F$8:$CQ$8,MP_Nov.20!$G40) -> 0 | BW11: =COUNTIF(MP_Nov.20!$F$9:$CQ$9,MP_Nov.20!$G40) -> 0 | BX11: =COUNTIF(MP_Nov.20!$F$10:$CQ$10,MP_Nov.20!$G40) -> 0 | BY11: =COUNTIF(MP_Nov.20!$F$11:$CQ$11,MP_Nov.20!$G40) -> 0 | BZ11: =COUNTIF(MP_Nov.20!$F$12:$CQ$12,MP_Nov.20!$G40) -> 0 | CA11: Empréstimo - Diss | CB11: =COUNTIF(MP_Dez.20!$F$7:$CT$7,MP_Dez.20!$G40) -> 0 | CC11: =COUNTIF(MP_Dez.20!$F$8:$CT$8,MP_Dez.20!$G40) -> 0 | CD11: =COUNTIF(MP_Dez.20!$F$9:$CT$9,MP_Dez.20!$G40) -> 0 | CE11: =COUNTIF(MP_Dez.20!$F$10:$CT$10,MP_Dez.20!$G40) -> 0 | CF11: =COUNTIF(MP_Dez.20!$F$11:$CT$11,MP_Dez.20!$G40) -> 0 | CG11: =COUNTIF(MP_Dez.20!$F$12:$CT$12,MP_Dez.20!$G40) -> 0
B12: Empréstimo - PD | C12: =COUNTIF(MP_Jan.20!$F$7:$CT$7,MP_Jan.20!$G41) -> 0 | D12: =COUNTIF(MP_Jan.20!$F$8:$CT$8,MP_Jan.20!$G41) -> 0 | E12: =COUNTIF(MP_Jan.20!$F$9:$CT$9,MP_Jan.20!$G41) -> 0 | F12: =COUNTIF(MP_Jan.20!$F$10:$CT$10,MP_Jan.20!$G41) -> 4 | G12: =COUNTIF(MP_Jan.20!$F$11:$CT$11,MP_Jan.20!$G41) -> 0 | H12: =COUNTIF(MP_Jan.20!$F$12:$CT$12,MP_Jan.20!$G41) -> 0 | I12: Empréstimo - PD | J12: =COUNTIF(MP_Fev.20!$F$7:$CN$7,MP_Fev.20!$G41) -> 0 | K12: =COUNTIF(MP_Fev.20!$F$8:$CN$8,MP_Fev.20!$G41) -> 0 | L12: =COUNTIF(MP_Fev.20!$F$9:$CN$9,MP_Fev.20!$G41) -> 0 | M12: =COUNTIF(MP_Fev.20!$F$10:$CN$10,MP_Fev.20!$G41) -> 0 | N12: =COUNTIF(MP_Fev.20!$F$11:$CN$11,MP_Fev.20!$G41) -> 0 | O12: =COUNTIF(MP_Fev.20!$F$12:$CN$12,MP_Fev.20!$G41) -> 0 | P12: Empréstimo - PD | Q12: =COUNTIF(MP_Mar.20!$F$7:$CT$7,MP_Mar.20!$G41) -> 0 | R12: =COUNTIF(MP_Mar.20!$F$8:$CT$8,MP_Mar.20!$G41) -> 0 | S12: =COUNTIF(MP_Mar.20!$F$9:$CT$9,MP_Mar.20!$G41) -> 0 | T12: =COUNTIF(MP_Mar.20!$F$10:$CT$10,MP_Mar.20!$G41) -> 0 | U12: =COUNTIF(MP_Mar.20!$F$11:$CT$11,MP_Mar.20!$G41) -> 0 | V12: =COUNTIF(MP_Mar.20!$F$12:$CT$12,MP_Mar.20!$G41) -> 0 | W12: Empréstimo - PD | X12: =COUNTIF(MP_Abr.20!$F$7:$CQ$7,MP_Abr.20!$G41) -> 0 | Y12: =COUNTIF(MP_Abr.20!$F$8:$CQ$8,MP_Abr.20!$G41) -> 0 | Z12: =COUNTIF(MP_Abr.20!$F$9:$CQ$9,MP_Abr.20!$G41) -> 0 | AA12: =COUNTIF(MP_Abr.20!$F$10:$CQ$10,MP_Abr.20!$G41) -> 0 | AB12: =COUNTIF(MP_Abr.20!$F$11:$CQ$11,MP_Abr.20!$G41) -> 0 | AC12: =COUNTIF(MP_Abr.20!$F$12:$CQ$12,MP_Abr.20!$G41) -> 0 | AD12: Empréstimo - PD | AE12: =COUNTIF(MP_Mai.20!$F$7:$CT$7,MP_Mai.20!$G41) -> 0 | AF12: =COUNTIF(MP_Mai.20!$F$8:$CT$8,MP_Mai.20!$G41) -> 0 | AG12: =COUNTIF(MP_Mai.20!$F$9:$CT$9,MP_Mai.20!$G41) -> 0 | AH12: =COUNTIF(MP_Mai.20!$F$10:$CT$10,MP_Mai.20!$G41) -> 0 | AI12: =COUNTIF(MP_Mai.20!$F$11:$CT$11,MP_Mai.20!$G41) -> 0 | AJ12: =COUNTIF(MP_Mai.20!$F$12:$CT$12,MP_Mai.20!$G41) -> 0 | AK12: Empréstimo - PD | AL12: =COUNTIF(MP_Jun.20!$F$7:$CQ$7,MP_Jun.20!$G41) -> 0 | AM12: =COUNTIF(MP_Jun.20!$F$8:$CQ$8,MP_Jun.20!$G41) -> 0 | AN12: =COUNTIF(MP_Jun.20!$F$9:$CQ$9,MP_Jun.20!$G41) -> 0 | AO12: =COUNTIF(MP_Jun.20!$F$10:$CQ$10,MP_Jun.20!$G41) -> 0 | AP12: =COUNTIF(MP_Jun.20!$F$11:$CQ$11,MP_Jun.20!$G41) -> 0 | AQ12: =COUNTIF(MP_Jun.20!$F$12:$CQ$12,MP_Jun.20!$G41) -> 0 | AR12: Empréstimo - PD | AS12: =COUNTIF(MP_Jul.20!$F$7:$CT$7,MP_Jul.20!$G41) -> 0 | AT12: =COUNTIF(MP_Jul.20!$F$8:$CT$8,MP_Jul.20!$G41) -> 0 | AU12: =COUNTIF(MP_Jul.20!$F$9:$CT$9,MP_Jul.20!$G41) -> 0 | AV12: =COUNTIF(MP_Jul.20!$F$10:$CT$10,MP_Jul.20!$G41) -> 0 | AW12: =COUNTIF(MP_Jul.20!$F$11:$CT$11,MP_Jul.20!$G41) -> 0 | AX12: =COUNTIF(MP_Jul.20!$F$12:$CT$12,MP_Jul.20!$G41) -> 0 | AY12: Empréstimo - PD | AZ12: =COUNTIF(MP_Ago.20!$F$7:$CT$7,MP_Ago.20!$G41) -> 0 | BA12: =COUNTIF(MP_Ago.20!$F$8:$CT$8,MP_Ago.20!$G41) -> 0 | BB12: =COUNTIF(MP_Ago.20!$F$9:$CT$9,MP_Ago.20!$G41) -> 0 | BC12: =COUNTIF(MP_Ago.20!$F$10:$CT$10,MP_Ago.20!$G41) -> 0 | BD12: =COUNTIF(MP_Ago.20!$F$11:$CT$11,MP_Ago.20!$G41) -> 0 | BE12: =COUNTIF(MP_Ago.20!$F$12:$CT$12,MP_Ago.20!$G41) -> 0 | BF12: Empréstimo - PD | BG12: =COUNTIF(MP_Set.20!$F$7:$CQ$7,MP_Set.20!$G41) -> 0 | BH12: =COUNTIF(MP_Set.20!$F$8:$CQ$8,MP_Set.20!$G41) -> 0 | BI12: =COUNTIF(MP_Set.20!$F$9:$CQ$9,MP_Set.20!$G41) -> 0 | BJ12: =COUNTIF(MP_Set.20!$F$10:$CQ$10,MP_Set.20!$G41) -> 0 | BK12: =COUNTIF(MP_Set.20!$F$11:$CQ$11,MP_Set.20!$G41) -> 0 | BL12: =COUNTIF(MP_Set.20!$F$12:$CQ$12,MP_Set.20!$G41) -> 0 | BM12: Empréstimo - PD | BN12: =COUNTIF(MP_Out.20!$F$7:$CT$7,MP_Out.20!$G41) -> 0 | BO12: =COUNTIF(MP_Out.20!$F$8:$CT$8,MP_Out.20!$G41) -> 0 | BP12: =COUNTIF(MP_Out.20!$F$9:$CT$9,MP_Out.20!$G41) -> 0 | BQ12: =COUNTIF(MP_Out.20!$F$10:$CT$10,MP_Out.20!$G41) -> 0 | BR12: =COUNTIF(MP_Out.20!$F$11:$CT$11,MP_Out.20!$G41) -> 0 | BS12: =COUNTIF(MP_Out.20!$F$12:$CT$12,MP_Out.20!$G41) -> 0 | BT12: Empréstimo - PD | BU12: =COUNTIF(MP_Nov.20!$F$7:$CQ$7,MP_Nov.20!$G41) -> 0 | BV12: =COUNTIF(MP_Nov.20!$F$8:$CQ$8,MP_Nov.20!$G41) -> 0 | BW12: =COUNTIF(MP_Nov.20!$F$9:$CQ$9,MP_Nov.20!$G41) -> 0 | BX12: =COUNTIF(MP_Nov.20!$F$10:$CQ$10,MP_Nov.20!$G41) -> 0 | BY12: =COUNTIF(MP_Nov.20!$F$11:$CQ$11,MP_Nov.20!$G41) -> 0 | BZ12: =COUNTIF(MP_Nov.20!$F$12:$CQ$12,MP_Nov.20!$G41) -> 0 | CA12: Empréstimo - PD | CB12: =COUNTIF(MP_Dez.20!$F$7:$CT$7,MP_Dez.20!$G41) -> 0 | CC12: =COUNTIF(MP_Dez.20!$F$8:$CT$8,MP_Dez.20!$G41) -> 0 | CD12: =COUNTIF(MP_Dez.20!$F$9:$CT$9,MP_Dez.20!$G41) -> 0 | CE12: =COUNTIF(MP_Dez.20!$F$10:$CT$10,MP_Dez.20!$G41) -> 0 | CF12: =COUNTIF(MP_Dez.20!$F$11:$CT$11,MP_Dez.20!$G41) -> 0 | CG12: =COUNTIF(MP_Dez.20!$F$12:$CT$12,MP_Dez.20!$G41) -> 0
B13: Empréstimo - Não medicamento | C13: =COUNTIF(MP_Jan.20!$F$7:$CT$7,MP_Jan.20!$G42) -> 0 | D13: =COUNTIF(MP_Jan.20!$F$8:$CT$8,MP_Jan.20!$G42) -> 0 | E13: =COUNTIF(MP_Jan.20!$F$9:$CT$9,MP_Jan.20!$G42) -> 0 | F13: =COUNTIF(MP_Jan.20!$F$10:$CT$10,MP_Jan.20!$G42) -> 0 | G13: =COUNTIF(MP_Jan.20!$F$11:$CT$11,MP_Jan.20!$G42) -> 0 | H13: =COUNTIF(MP_Jan.20!$F$12:$CT$12,MP_Jan.20!$G42) -> 0 | I13: Empréstimo - Não medicamento | J13: =COUNTIF(MP_Fev.20!$F$7:$CN$7,MP_Fev.20!$G42) -> 0 | K13: =COUNTIF(MP_Fev.20!$F$8:$CN$8,MP_Fev.20!$G42) -> 0 | L13: =COUNTIF(MP_Fev.20!$F$9:$CN$9,MP_Fev.20!$G42) -> 0 | M13: =COUNTIF(MP_Fev.20!$F$10:$CN$10,MP_Fev.20!$G42) -> 0 | N13: =COUNTIF(MP_Fev.20!$F$11:$CN$11,MP_Fev.20!$G42) -> 0 | O13: =COUNTIF(MP_Fev.20!$F$12:$CN$12,MP_Fev.20!$G42) -> 0 | P13: Empréstimo - Não medicamento | Q13: =COUNTIF(MP_Mar.20!$F$7:$CT$7,MP_Mar.20!$G42) -> 0 | R13: =COUNTIF(MP_Mar.20!$F$8:$CT$8,MP_Mar.20!$G42) -> 0 | S13: =COUNTIF(MP_Mar.20!$F$9:$CT$9,MP_Mar.20!$G42) -> 0 | T13: =COUNTIF(MP_Mar.20!$F$10:$CT$10,MP_Mar.20!$G42) -> 0 | U13: =COUNTIF(MP_Mar.20!$F$11:$CT$11,MP_Mar.20!$G42) -> 0 | V13: =COUNTIF(MP_Mar.20!$F$12:$CT$12,MP_Mar.20!$G42) -> 0 | W13: Empréstimo - Não medicamento | X13: =COUNTIF(MP_Abr.20!$F$7:$CQ$7,MP_Abr.20!$G42) -> 0 | Y13: =COUNTIF(MP_Abr.20!$F$8:$CQ$8,MP_Abr.20!$G42) -> 0 | Z13: =COUNTIF(MP_Abr.20!$F$9:$CQ$9,MP_Abr.20!$G42) -> 0 | AA13: =COUNTIF(MP_Abr.20!$F$10:$CQ$10,MP_Abr.20!$G42) -> 0 | AB13: =COUNTIF(MP_Abr.20!$F$11:$CQ$11,MP_Abr.20!$G42) -> 0 | AC13: =COUNTIF(MP_Abr.20!$F$12:$CQ$12,MP_Abr.20!$G42) -> 0 | AD13: Empréstimo - Não medicamento | AE13: =COUNTIF(MP_Mai.20!$F$7:$CT$7,MP_Mai.20!$G42) -> 0 | AF13: =COUNTIF(MP_Mai.20!$F$8:$CT$8,MP_Mai.20!$G42) -> 0 | AG13: =COUNTIF(MP_Mai.20!$F$9:$CT$9,MP_Mai.20!$G42) -> 0 | AH13: =COUNTIF(MP_Mai.20!$F$10:$CT$10,MP_Mai.20!$G42) -> 0 | AI13: =COUNTIF(MP_Mai.20!$F$11:$CT$11,MP_Mai.20!$G42) -> 0 | AJ13: =COUNTIF(MP_Mai.20!$F$12:$CT$12,MP_Mai.20!$G42) -> 0 | AK13: Empréstimo - Não medicamento | AL13: =COUNTIF(MP_Jun.20!$F$7:$CQ$7,MP_Jun.20!$G42) -> 0 | AM13: =COUNTIF(MP_Jun.20!$F$8:$CQ$8,MP_Jun.20!$G42) -> 0 | AN13: =COUNTIF(MP_Jun.20!$F$9:$CQ$9,MP_Jun.20!$G42) -> 0 | AO13: =COUNTIF(MP_Jun.20!$F$10:$CQ$10,MP_Jun.20!$G42) -> 0 | AP13: =COUNTIF(MP_Jun.20!$F$11:$CQ$11,MP_Jun.20!$G42) -> 0 | AQ13: =COUNTIF(MP_Jun.20!$F$12:$CQ$12,MP_Jun.20!$G42) -> 0 | AR13: Empréstimo - Não medicamento | AS13: =COUNTIF(MP_Jul.20!$F$7:$CT$7,MP_Jul.20!$G42) -> 0 | AT13: =COUNTIF(MP_Jul.20!$F$8:$CT$8,MP_Jul.20!$G42) -> 0 | AU13: =COUNTIF(MP_Jul.20!$F$9:$CT$9,MP_Jul.20!$G42) -> 0 | AV13: =COUNTIF(MP_Jul.20!$F$10:$CT$10,MP_Jul.20!$G42) -> 0 | AW13: =COUNTIF(MP_Jul.20!$F$11:$CT$11,MP_Jul.20!$G42) -> 0 | AX13: =COUNTIF(MP_Jul.20!$F$12:$CT$12,MP_Jul.20!$G42) -> 0 | AY13: Empréstimo - Não medicamento | AZ13: =COUNTIF(MP_Ago.20!$F$7:$CT$7,MP_Ago.20!$G42) -> 0 | BA13: =COUNTIF(MP_Ago.20!$F$8:$CT$8,MP_Ago.20!$G42) -> 0 | BB13: =COUNTIF(MP_Ago.20!$F$9:$CT$9,MP_Ago.20!$G42) -> 0 | BC13: =COUNTIF(MP_Ago.20!$F$10:$CT$10,MP_Ago.20!$G42) -> 0 | BD13: =COUNTIF(MP_Ago.20!$F$11:$CT$11,MP_Ago.20!$G42) -> 0 | BE13: =COUNTIF(MP_Ago.20!$F$12:$CT$12,MP_Ago.20!$G42) -> 0 | BF13: Empréstimo - Não medicamento | BG13: =COUNTIF(MP_Set.20!$F$7:$CQ$7,MP_Set.20!$G42) -> 0 | BH13: =COUNTIF(MP_Set.20!$F$8:$CQ$8,MP_Set.20!$G42) -> 0 | BI13: =COUNTIF(MP_Set.20!$F$9:$CQ$9,MP_Set.20!$G42) -> 0 | BJ13: =COUNTIF(MP_Set.20!$F$10:$CQ$10,MP_Set.20!$G42) -> 0 | BK13: =COUNTIF(MP_Set.20!$F$11:$CQ$11,MP_Set.20!$G42) -> 0 | BL13: =COUNTIF(MP_Set.20!$F$12:$CQ$12,MP_Set.20!$G42) -> 0 | BM13: Empréstimo - Não medicamento | BN13: =COUNTIF(MP_Out.20!$F$7:$CT$7,MP_Out.20!$G42) -> 0 | BO13: =COUNTIF(MP_Out.20!$F$8:$CT$8,MP_Out.20!$G42) -> 0 | BP13: =COUNTIF(MP_Out.20!$F$9:$CT$9,MP_Out.20!$G42) -> 0 | BQ13: =COUNTIF(MP_Out.20!$F$10:$CT$10,MP_Out.20!$G42) -> 0 | BR13: =COUNTIF(MP_Out.20!$F$11:$CT$11,MP_Out.20!$G42) -> 0 | BS13: =COUNTIF(MP_Out.20!$F$12:$CT$12,MP_Out.20!$G42) -> 0 | BT13: Empréstimo - Não medicamento | BU13: =COUNTIF(MP_Nov.20!$F$7:$CQ$7,MP_Nov.20!$G42) -> 0 | BV13: =COUNTIF(MP_Nov.20!$F$8:$CQ$8,MP_Nov.20!$G42) -> 0 | BW13: =COUNTIF(MP_Nov.20!$F$9:$CQ$9,MP_Nov.20!$G42) -> 0 | BX13: =COUNTIF(MP_Nov.20!$F$10:$CQ$10,MP_Nov.20!$G42) -> 0 | BY13: =COUNTIF(MP_Nov.20!$F$11:$CQ$11,MP_Nov.20!$G42) -> 0 | BZ13: =COUNTIF(MP_Nov.20!$F$12:$CQ$12,MP_Nov.20!$G42) -> 0 | CA13: Empréstimo - Não medicamento | CB13: =COUNTIF(MP_Dez.20!$F$7:$CT$7,MP_Dez.20!$G42) -> 0 | CC13: =COUNTIF(MP_Dez.20!$F$8:$CT$8,MP_Dez.20!$G42) -> 0 | CD13: =COUNTIF(MP_Dez.20!$F$9:$CT$9,MP_Dez.20!$G42) -> 0 | CE13: =COUNTIF(MP_Dez.20!$F$10:$CT$10,MP_Dez.20!$G42) -> 0 | CF13: =COUNTIF(MP_Dez.20!$F$11:$CT$11,MP_Dez.20!$G42) -> 0 | CG13: =COUNTIF(MP_Dez.20!$F$12:$CT$12,MP_Dez.20!$G42) -> 0
B14: Empréstimo - Suporte analítico | C14: =COUNTIF(MP_Jan.20!$F$7:$CT$7,MP_Jan.20!$G43) -> 0 | D14: =COUNTIF(MP_Jan.20!$F$8:$CT$8,MP_Jan.20!$G43) -> 0 | E14: =COUNTIF(MP_Jan.20!$F$9:$CT$9,MP_Jan.20!$G43) -> 0 | F14: =COUNTIF(MP_Jan.20!$F$10:$CT$10,MP_Jan.20!$G43) -> 0 | G14: =COUNTIF(MP_Jan.20!$F$11:$CT$11,MP_Jan.20!$G43) -> 0 | H14: =COUNTIF(MP_Jan.20!$F$12:$CT$12,MP_Jan.20!$G43) -> 0 | I14: Empréstimo - Suporte analítico | J14: =COUNTIF(MP_Fev.20!$F$7:$CN$7,MP_Fev.20!$G43) -> 0 | K14: =COUNTIF(MP_Fev.20!$F$8:$CN$8,MP_Fev.20!$G43) -> 0 | L14: =COUNTIF(MP_Fev.20!$F$9:$CN$9,MP_Fev.20!$G43) -> 0 | M14: =COUNTIF(MP_Fev.20!$F$10:$CN$10,MP_Fev.20!$G43) -> 0 | N14: =COUNTIF(MP_Fev.20!$F$11:$CN$11,MP_Fev.20!$G43) -> 0 | O14: =COUNTIF(MP_Fev.20!$F$12:$CN$12,MP_Fev.20!$G43) -> 0 | P14: Empréstimo - Suporte analítico | Q14: =COUNTIF(MP_Mar.20!$F$7:$CT$7,MP_Mar.20!$G43) -> 0 | R14: =COUNTIF(MP_Mar.20!$F$8:$CT$8,MP_Mar.20!$G43) -> 0 | S14: =COUNTIF(MP_Mar.20!$F$9:$CT$9,MP_Mar.20!$G43) -> 0 | T14: =COUNTIF(MP_Mar.20!$F$10:$CT$10,MP_Mar.20!$G43) -> 0 | U14: =COUNTIF(MP_Mar.20!$F$11:$CT$11,MP_Mar.20!$G43) -> 0 | V14: =COUNTIF(MP_Mar.20!$F$12:$CT$12,MP_Mar.20!$G43) -> 0 | W14: Empréstimo - Suporte analítico | X14: =COUNTIF(MP_Abr.20!$F$7:$CQ$7,MP_Abr.20!$G43) -> 0 | Y14: =COUNTIF(MP_Abr.20!$F$8:$CQ$8,MP_Abr.20!$G43) -> 0 | Z14: =COUNTIF(MP_Abr.20!$F$9:$CQ$9,MP_Abr.20!$G43) -> 0 | AA14: =COUNTIF(MP_Abr.20!$F$10:$CQ$10,MP_Abr.20!$G43) -> 0 | AB14: =COUNTIF(MP_Abr.20!$F$11:$CQ$11,MP_Abr.20!$G43) -> 0 | AC14: =COUNTIF(MP_Abr.20!$F$12:$CQ$12,MP_Abr.20!$G43) -> 0 | AD14: Empréstimo - Suporte analítico | AE14: =COUNTIF(MP_Mai.20!$F$7:$CT$7,MP_Mai.20!$G43) -> 0 | AF14: =COUNTIF(MP_Mai.20!$F$8:$CT$8,MP_Mai.20!$G43) -> 0 | AG14: =COUNTIF(MP_Mai.20!$F$9:$CT$9,MP_Mai.20!$G43) -> 0 | AH14: =COUNTIF(MP_Mai.20!$F$10:$CT$10,MP_Mai.20!$G43) -> 0 | AI14: =COUNTIF(MP_Mai.20!$F$11:$CT$11,MP_Mai.20!$G43) -> 0 | AJ14: =COUNTIF(MP_Mai.20!$F$12:$CT$12,MP_Mai.20!$G43) -> 0 | AK14: Empréstimo - Suporte analítico | AL14: =COUNTIF(MP_Jun.20!$F$7:$CQ$7,MP_Jun.20!$G43) -> 0 | AM14: =COUNTIF(MP_Jun.20!$F$8:$CQ$8,MP_Jun.20!$G43) -> 0 | AN14: =COUNTIF(MP_Jun.20!$F$9:$CQ$9,MP_Jun.20!$G43) -> 0 | AO14: =COUNTIF(MP_Jun.20!$F$10:$CQ$10,MP_Jun.20!$G43) -> 0 | AP14: =COUNTIF(MP_Jun.20!$F$11:$CQ$11,MP_Jun.20!$G43) -> 0 | AQ14: =COUNTIF(MP_Jun.20!$F$12:$CQ$12,MP_Jun.20!$G43) -> 0 | AR14: Empréstimo - Suporte analítico | AS14: =COUNTIF(MP_Jul.20!$F$7:$CT$7,MP_Jul.20!$G43) -> 0 | AT14: =COUNTIF(MP_Jul.20!$F$8:$CT$8,MP_Jul.20!$G43) -> 0 | AU14: =COUNTIF(MP_Jul.20!$F$9:$CT$9,MP_Jul.20!$G43) -> 0 | AV14: =COUNTIF(MP_Jul.20!$F$10:$CT$10,MP_Jul.20!$G43) -> 0 | AW14: =COUNTIF(MP_Jul.20!$F$11:$CT$11,MP_Jul.20!$G43) -> 0 | AX14: =COUNTIF(MP_Jul.20!$F$12:$CT$12,MP_Jul.20!$G43) -> 0 | AY14: Empréstimo - Suporte analítico | AZ14: =COUNTIF(MP_Ago.20!$F$7:$CT$7,MP_Ago.20!$G43) -> 0 | BA14: =COUNTIF(MP_Ago.20!$F$8:$CT$8,MP_Ago.20!$G43) -> 0 | BB14: =COUNTIF(MP_Ago.20!$F$9:$CT$9,MP_Ago.20!$G43) -> 0 | BC14: =COUNTIF(MP_Ago.20!$F$10:$CT$10,MP_Ago.20!$G43) -> 0 | BD14: =COUNTIF(MP_Ago.20!$F$11:$CT$11,MP_Ago.20!$G43) -> 0 | BE14: =COUNTIF(MP_Ago.20!$F$12:$CT$12,MP_Ago.20!$G43) -> 0 | BF14: Empréstimo - Suporte analítico | BG14: =COUNTIF(MP_Set.20!$F$7:$CQ$7,MP_Set.20!$G43) -> 0 | BH14: =COUNTIF(MP_Set.20!$F$8:$CQ$8,MP_Set.20!$G43) -> 0 | BI14: =COUNTIF(MP_Set.20!$F$9:$CQ$9,MP_Set.20!$G43) -> 0 | BJ14: =COUNTIF(MP_Set.20!$F$10:$CQ$10,MP_Set.20!$G43) -> 0 | BK14: =COUNTIF(MP_Set.20!$F$11:$CQ$11,MP_Set.20!$G43) -> 0 | BL14: =COUNTIF(MP_Set.20!$F$12:$CQ$12,MP_Set.20!$G43) -> 0 | BM14: Empréstimo - Suporte analítico | BN14: =COUNTIF(MP_Out.20!$F$7:$CT$7,MP_Out.20!$G43) -> 0 | BO14: =COUNTIF(MP_Out.20!$F$8:$CT$8,MP_Out.20!$G43) -> 0 | BP14: =COUNTIF(MP_Out.20!$F$9:$CT$9,MP_Out.20!$G43) -> 0 | BQ14: =COUNTIF(MP_Out.20!$F$10:$CT$10,MP_Out.20!$G43) -> 0 | BR14: =COUNTIF(MP_Out.20!$F$11:$CT$11,MP_Out.20!$G43) -> 0 | BS14: =COUNTIF(MP_Out.20!$F$12:$CT$12,MP_Out.20!$G43) -> 0 | BT14: Empréstimo - Suporte analítico | BU14: =COUNTIF(MP_Nov.20!$F$7:$CQ$7,MP_Nov.20!$G43) -> 0 | BV14: =COUNTIF(MP_Nov.20!$F$8:$CQ$8,MP_Nov.20!$G43) -> 0 | BW14: =COUNTIF(MP_Nov.20!$F$9:$CQ$9,MP_Nov.20!$G43) -> 0 | BX14: =COUNTIF(MP_Nov.20!$F$10:$CQ$10,MP_Nov.20!$G43) -> 0 | BY14: =COUNTIF(MP_Nov.20!$F$11:$CQ$11,MP_Nov.20!$G43) -> 0 | BZ14: =COUNTIF(MP_Nov.20!$F$12:$CQ$12,MP_Nov.20!$G43) -> 0 | CA14: Empréstimo - Suporte analítico | CB14: =COUNTIF(MP_Dez.20!$F$7:$CT$7,MP_Dez.20!$G43) -> 0 | CC14: =COUNTIF(MP_Dez.20!$F$8:$CT$8,MP_Dez.20!$G43) -> 0 | CD14: =COUNTIF(MP_Dez.20!$F$9:$CT$9,MP_Dez.20!$G43) -> 0 | CE14: =COUNTIF(MP_Dez.20!$F$10:$CT$10,MP_Dez.20!$G43) -> 0 | CF14: =COUNTIF(MP_Dez.20!$F$11:$CT$11,MP_Dez.20!$G43) -> 0 | CG14: =COUNTIF(MP_Dez.20!$F$12:$CT$12,MP_Dez.20!$G43) -> 0
B15: Empréstimo - Troubleshooting | C15: =COUNTIF(MP_Jan.20!$F$7:$CT$7,MP_Jan.20!$G44) -> 0 | D15: =COUNTIF(MP_Jan.20!$F$8:$CT$8,MP_Jan.20!$G44) -> 0 | E15: =COUNTIF(MP_Jan.20!$F$9:$CT$9,MP_Jan.20!$G44) -> 0 | F15: =COUNTIF(MP_Jan.20!$F$10:$CT$10,MP_Jan.20!$G44) -> 0 | G15: =COUNTIF(MP_Jan.20!$F$11:$CT$11,MP_Jan.20!$G44) -> 0 | H15: =COUNTIF(MP_Jan.20!$F$12:$CT$12,MP_Jan.20!$G44) -> 0 | I15: Empréstimo - Troubleshooting | J15: =COUNTIF(MP_Fev.20!$F$7:$CN$7,MP_Fev.20!$G44) -> 0 | K15: =COUNTIF(MP_Fev.20!$F$8:$CN$8,MP_Fev.20!$G44) -> 0 | L15: =COUNTIF(MP_Fev.20!$F$9:$CN$9,MP_Fev.20!$G44) -> 0 | M15: =COUNTIF(MP_Fev.20!$F$10:$CN$10,MP_Fev.20!$G44) -> 0 | N15: =COUNTIF(MP_Fev.20!$F$11:$CN$11,MP_Fev.20!$G44) -> 0 | O15: =COUNTIF(MP_Fev.20!$F$12:$CN$12,MP_Fev.20!$G44) -> 0 | P15: Empréstimo - Troubleshooting | Q15: =COUNTIF(MP_Mar.20!$F$7:$CT$7,MP_Mar.20!$G44) -> 0 | R15: =COUNTIF(MP_Mar.20!$F$8:$CT$8,MP_Mar.20!$G44) -> 0 | S15: =COUNTIF(MP_Mar.20!$F$9:$CT$9,MP_Mar.20!$G44) -> 0 | T15: =COUNTIF(MP_Mar.20!$F$10:$CT$10,MP_Mar.20!$G44) -> 0 | U15: =COUNTIF(MP_Mar.20!$F$11:$CT$11,MP_Mar.20!$G44) -> 0 | V15: =COUNTIF(MP_Mar.20!$F$12:$CT$12,MP_Mar.20!$G44) -> 0 | W15: Empréstimo - Troubleshooting | X15: =COUNTIF(MP_Abr.20!$F$7:$CQ$7,MP_Abr.20!$G44) -> 0 | Y15: =COUNTIF(MP_Abr.20!$F$8:$CQ$8,MP_Abr.20!$G44) -> 0 | Z15: =COUNTIF(MP_Abr.20!$F$9:$CQ$9,MP_Abr.20!$G44) -> 0 | AA15: =COUNTIF(MP_Abr.20!$F$10:$CQ$10,MP_Abr.20!$G44) -> 0 | AB15: =COUNTIF(MP_Abr.20!$F$11:$CQ$11,MP_Abr.20!$G44) -> 0 | AC15: =COUNTIF(MP_Abr.20!$F$12:$CQ$12,MP_Abr.20!$G44) -> 0 | AD15: Empréstimo - Troubleshooting | AE15: =COUNTIF(MP_Mai.20!$F$7:$CT$7,MP_Mai.20!$G44) -> 0 | AF15: =COUNTIF(MP_Mai.20!$F$8:$CT$8,MP_Mai.20!$G44) -> 0 | AG15: =COUNTIF(MP_Mai.20!$F$9:$CT$9,MP_Mai.20!$G44) -> 0 | AH15: =COUNTIF(MP_Mai.20!$F$10:$CT$10,MP_Mai.20!$G44) -> 0 | AI15: =COUNTIF(MP_Mai.20!$F$11:$CT$11,MP_Mai.20!$G44) -> 0 | AJ15: =COUNTIF(MP_Mai.20!$F$12:$CT$12,MP_Mai.20!$G44) -> 0 | AK15: Empréstimo - Troubleshooting | AL15: =COUNTIF(MP_Jun.20!$F$7:$CQ$7,MP_Jun.20!$G44) -> 0 | AM15: =COUNTIF(MP_Jun.20!$F$8:$CQ$8,MP_Jun.20!$G44) -> 0 | AN15: =COUNTIF(MP_Jun.20!$F$9:$CQ$9,MP_Jun.20!$G44) -> 0 | AO15: =COUNTIF(MP_Jun.20!$F$10:$CQ$10,MP_Jun.20!$G44) -> 0 | AP15: =COUNTIF(MP_Jun.20!$F$11:$CQ$11,MP_Jun.20!$G44) -> 0 | AQ15: =COUNTIF(MP_Jun.20!$F$12:$CQ$12,MP_Jun.20!$G44) -> 0 | AR15: Empréstimo - Troubleshooting | AS15: =COUNTIF(MP_Jul.20!$F$7:$CT$7,MP_Jul.20!$G44) -> 0 | AT15: =COUNTIF(MP_Jul.20!$F$8:$CT$8,MP_Jul.20!$G44) -> 0 | AU15: =COUNTIF(MP_Jul.20!$F$9:$CT$9,MP_Jul.20!$G44) -> 0 | AV15: =COUNTIF(MP_Jul.20!$F$10:$CT$10,MP_Jul.20!$G44) -> 0 | AW15: =COUNTIF(MP_Jul.20!$F$11:$CT$11,MP_Jul.20!$G44) -> 0 | AX15: =COUNTIF(MP_Jul.20!$F$12:$CT$12,MP_Jul.20!$G44) -> 0 | AY15: Empréstimo - Troubleshooting | AZ15: =COUNTIF(MP_Ago.20!$F$7:$CT$7,MP_Ago.20!$G44) -> 0 | BA15: =COUNTIF(MP_Ago.20!$F$8:$CT$8,MP_Ago.20!$G44) -> 0 | BB15: =COUNTIF(MP_Ago.20!$F$9:$CT$9,MP_Ago.20!$G44) -> 0 | BC15: =COUNTIF(MP_Ago.20!$F$10:$CT$10,MP_Ago.20!$G44) -> 0 | BD15: =COUNTIF(MP_Ago.20!$F$11:$CT$11,MP_Ago.20!$G44) -> 0 | BE15: =COUNTIF(MP_Ago.20!$F$12:$CT$12,MP_Ago.20!$G44) -> 0 | BF15: Empréstimo - Troubleshooting | BG15: =COUNTIF(MP_Set.20!$F$7:$CQ$7,MP_Set.20!$G44) -> 0 | BH15: =COUNTIF(MP_Set.20!$F$8:$CQ$8,MP_Set.20!$G44) -> 0 | BI15: =COUNTIF(MP_Set.20!$F$9:$CQ$9,MP_Set.20!$G44) -> 0 | BJ15: =COUNTIF(MP_Set.20!$F$10:$CQ$10,MP_Set.20!$G44) -> 0 | BK15: =COUNTIF(MP_Set.20!$F$11:$CQ$11,MP_Set.20!$G44) -> 0 | BL15: =COUNTIF(MP_Set.20!$F$12:$CQ$12,MP_Set.20!$G44) -> 0 | BM15: Empréstimo - Troubleshooting | BN15: =COUNTIF(MP_Out.20!$F$7:$CT$7,MP_Out.20!$G44) -> 0 | BO15: =COUNTIF(MP_Out.20!$F$8:$CT$8,MP_Out.20!$G44) -> 0 | BP15: =COUNTIF(MP_Out.20!$F$9:$CT$9,MP_Out.20!$G44) -> 0 | BQ15: =COUNTIF(MP_Out.20!$F$10:$CT$10,MP_Out.20!$G44) -> 0 | BR15: =COUNTIF(MP_Out.20!$F$11:$CT$11,MP_Out.20!$G44) -> 0 | BS15: =COUNTIF(MP_Out.20!$F$12:$CT$12,MP_Out.20!$G44) -> 0 | BT15: Empréstimo - Troubleshooting | BU15: =COUNTIF(MP_Nov.20!$F$7:$CQ$7,MP_Nov.20!$G44) -> 0 | BV15: =COUNTIF(MP_Nov.20!$F$8:$CQ$8,MP_Nov.20!$G44) -> 0 | BW15: =COUNTIF(MP_Nov.20!$F$9:$CQ$9,MP_Nov.20!$G44) -> 0 | BX15: =COUNTIF(MP_Nov.20!$F$10:$CQ$10,MP_Nov.20!$G44) -> 0 | BY15: =COUNTIF(MP_Nov.20!$F$11:$CQ$11,MP_Nov.20!$G44) -> 0 | BZ15: =COUNTIF(MP_Nov.20!$F$12:$CQ$12,MP_Nov.20!$G44) -> 0 | CA15: Empréstimo - Troubleshooting | CB15: =COUNTIF(MP_Dez.20!$F$7:$CT$7,MP_Dez.20!$G44) -> 0 | CC15: =COUNTIF(MP_Dez.20!$F$8:$CT$8,MP_Dez.20!$G44) -> 0 | CD15: =COUNTIF(MP_Dez.20!$F$9:$CT$9,MP_Dez.20!$G44) -> 0 | CE15: =COUNTIF(MP_Dez.20!$F$10:$CT$10,MP_Dez.20!$G44) -> 0 | CF15: =COUNTIF(MP_Dez.20!$F$11:$CT$11,MP_Dez.20!$G44) -> 0 | CG15: =COUNTIF(MP_Dez.20!$F$12:$CT$12,MP_Dez.20!$G44) -> 0
B16: Manutenção | C16: =COUNTIF(MP_Jan.20!$F$7:$CT$7,MP_Jan.20!$G45) -> 0 | D16: =COUNTIF(MP_Jan.20!$F$8:$CT$8,MP_Jan.20!$G45) -> 0 | E16: =COUNTIF(MP_Jan.20!$F$9:$CT$9,MP_Jan.20!$G45) -> 0 | F16: =COUNTIF(MP_Jan.20!$F$10:$CT$10,MP_Jan.20!$G45) -> 0 | G16: =COUNTIF(MP_Jan.20!$F$11:$CT$11,MP_Jan.20!$G45) -> 0 | H16: =COUNTIF(MP_Jan.20!$F$12:$CT$12,MP_Jan.20!$G45) -> 0 | I16: Manutenção | J16: =COUNTIF(MP_Fev.20!$F$7:$CN$7,MP_Fev.20!$G45) -> 0 | K16: =COUNTIF(MP_Fev.20!$F$8:$CN$8,MP_Fev.20!$G45) -> 0 | L16: =COUNTIF(MP_Fev.20!$F$9:$CN$9,MP_Fev.20!$G45) -> 0 | M16: =COUNTIF(MP_Fev.20!$F$10:$CN$10,MP_Fev.20!$G45) -> 0 | N16: =COUNTIF(MP_Fev.20!$F$11:$CN$11,MP_Fev.20!$G45) -> 0 | O16: =COUNTIF(MP_Fev.20!$F$12:$CN$12,MP_Fev.20!$G45) -> 0 | P16: Manutenção | Q16: =COUNTIF(MP_Mar.20!$F$7:$CT$7,MP_Mar.20!$G45) -> 0 | R16: =COUNTIF(MP_Mar.20!$F$8:$CT$8,MP_Mar.20!$G45) -> 0 | S16: =COUNTIF(MP_Mar.20!$F$9:$CT$9,MP_Mar.20!$G45) -> 0 | T16: =COUNTIF(MP_Mar.20!$F$10:$CT$10,MP_Mar.20!$G45) -> 0 | U16: =COUNTIF(MP_Mar.20!$F$11:$CT$11,MP_Mar.20!$G45) -> 0 | V16: =COUNTIF(MP_Mar.20!$F$12:$CT$12,MP_Mar.20!$G45) -> 0 | W16: Manutenção | X16: =COUNTIF(MP_Abr.20!$F$7:$CQ$7,MP_Abr.20!$G45) -> 0 | Y16: =COUNTIF(MP_Abr.20!$F$8:$CQ$8,MP_Abr.20!$G45) -> 0 | Z16: =COUNTIF(MP_Abr.20!$F$9:$CQ$9,MP_Abr.20!$G45) -> 0 | AA16: =COUNTIF(MP_Abr.20!$F$10:$CQ$10,MP_Abr.20!$G45) -> 0 | AB16: =COUNTIF(MP_Abr.20!$F$11:$CQ$11,MP_Abr.20!$G45) -> 0 | AC16: =COUNTIF(MP_Abr.20!$F$12:$CQ$12,MP_Abr.20!$G45) -> 0 | AD16: Manutenção | AE16: =COUNTIF(MP_Mai.20!$F$7:$CT$7,MP_Mai.20!$G45) -> 0 | AF16: =COUNTIF(MP_Mai.20!$F$8:$CT$8,MP_Mai.20!$G45) -> 0 | AG16: =COUNTIF(MP_Mai.20!$F$9:$CT$9,MP_Mai.20!$G45) -> 0 | AH16: =COUNTIF(MP_Mai.20!$F$10:$CT$10,MP_Mai.20!$G45) -> 0 | AI16: =COUNTIF(MP_Mai.20!$F$11:$CT$11,MP_Mai.20!$G45) -> 0 | AJ16: =COUNTIF(MP_Mai.20!$F$12:$CT$12,MP_Mai.20!$G45) -> 0 | AK16: Manutenção | AL16: =COUNTIF(MP_Jun.20!$F$7:$CQ$7,MP_Jun.20!$G45) -> 0 | AM16: =COUNTIF(MP_Jun.20!$F$8:$CQ$8,MP_Jun.20!$G45) -> 0 | AN16: =COUNTIF(MP_Jun.20!$F$9:$CQ$9,MP_Jun.20!$G45) -> 0 | AO16: =COUNTIF(MP_Jun.20!$F$10:$CQ$10,MP_Jun.20!$G45) -> 0 | AP16: =COUNTIF(MP_Jun.20!$F$11:$CQ$11,MP_Jun.20!$G45) -> 0 | AQ16: =COUNTIF(MP_Jun.20!$F$12:$CQ$12,MP_Jun.20!$G45) -> 0 | AR16: Manutenção | AS16: =COUNTIF(MP_Jul.20!$F$7:$CT$7,MP_Jul.20!$G45) -> 0 | AT16: =COUNTIF(MP_Jul.20!$F$8:$CT$8,MP_Jul.20!$G45) -> 0 | AU16: =COUNTIF(MP_Jul.20!$F$9:$CT$9,MP_Jul.20!$G45) -> 0 | AV16: =COUNTIF(MP_Jul.20!$F$10:$CT$10,MP_Jul.20!$G45) -> 0 | AW16: =COUNTIF(MP_Jul.20!$F$11:$CT$11,MP_Jul.20!$G45) -> 0 | AX16: =COUNTIF(MP_Jul.20!$F$12:$CT$12,MP_Jul.20!$G45) -> 0 | AY16: Manutenção | AZ16: =COUNTIF(MP_Ago.20!$F$7:$CT$7,MP_Ago.20!$G45) -> 0 | BA16: =COUNTIF(MP_Ago.20!$F$8:$CT$8,MP_Ago.20!$G45) -> 0 | BB16: =COUNTIF(MP_Ago.20!$F$9:$CT$9,MP_Ago.20!$G45) -> 0 | BC16: =COUNTIF(MP_Ago.20!$F$10:$CT$10,MP_Ago.20!$G45) -> 0 | BD16: =COUNTIF(MP_Ago.20!$F$11:$CT$11,MP_Ago.20!$G45) -> 0 | BE16: =COUNTIF(MP_Ago.20!$F$12:$CT$12,MP_Ago.20!$G45) -> 0 | BF16: Manutenção | BG16: =COUNTIF(MP_Set.20!$F$7:$CQ$7,MP_Set.20!$G45) -> 0 | BH16: =COUNTIF(MP_Set.20!$F$8:$CQ$8,MP_Set.20!$G45) -> 0 | BI16: =COUNTIF(MP_Set.20!$F$9:$CQ$9,MP_Set.20!$G45) -> 0 | BJ16: =COUNTIF(MP_Set.20!$F$10:$CQ$10,MP_Set.20!$G45) -> 0 | BK16: =COUNTIF(MP_Set.20!$F$11:$CQ$11,MP_Set.20!$G45) -> 0 | BL16: =COUNTIF(MP_Set.20!$F$12:$CQ$12,MP_Set.20!$G45) -> 0 | BM16: Manutenção | BN16: =COUNTIF(MP_Out.20!$F$7:$CT$7,MP_Out.20!$G45) -> 0 | BO16: =COUNTIF(MP_Out.20!$F$8:$CT$8,MP_Out.20!$G45) -> 0 | BP16: =COUNTIF(MP_Out.20!$F$9:$CT$9,MP_Out.20!$G45) -> 0 | BQ16: =COUNTIF(MP_Out.20!$F$10:$CT$10,MP_Out.20!$G45) -> 0 | BR16: =COUNTIF(MP_Out.20!$F$11:$CT$11,MP_Out.20!$G45) -> 0 | BS16: =COUNTIF(MP_Out.20!$F$12:$CT$12,MP_Out.20!$G45) -> 0 | BT16: Manutenção | BU16: =COUNTIF(MP_Nov.20!$F$7:$CQ$7,MP_Nov.20!$G45) -> 0 | BV16: =COUNTIF(MP_Nov.20!$F$8:$CQ$8,MP_Nov.20!$G45) -> 0 | BW16: =COUNTIF(MP_Nov.20!$F$9:$CQ$9,MP_Nov.20!$G45) -> 0 | BX16: =COUNTIF(MP_Nov.20!$F$10:$CQ$10,MP_Nov.20!$G45) -> 0 | BY16: =COUNTIF(MP_Nov.20!$F$11:$CQ$11,MP_Nov.20!$G45) -> 0 | BZ16: =COUNTIF(MP_Nov.20!$F$12:$CQ$12,MP_Nov.20!$G45) -> 0 | CA16: Manutenção | CB16: =COUNTIF(MP_Dez.20!$F$7:$CT$7,MP_Dez.20!$G45) -> 0 | CC16: =COUNTIF(MP_Dez.20!$F$8:$CT$8,MP_Dez.20!$G45) -> 0 | CD16: =COUNTIF(MP_Dez.20!$F$9:$CT$9,MP_Dez.20!$G45) -> 0 | CE16: =COUNTIF(MP_Dez.20!$F$10:$CT$10,MP_Dez.20!$G45) -> 0 | CF16: =COUNTIF(MP_Dez.20!$F$11:$CT$11,MP_Dez.20!$G45) -> 0 | CG16: =COUNTIF(MP_Dez.20!$F$12:$CT$12,MP_Dez.20!$G45) -> 0
B17: Livre | C17: =COUNTIF(MP_Jan.20!$F$7:$CT$7,MP_Jan.20!$G46) -> 2 | D17: =COUNTIF(MP_Jan.20!$F$8:$CT$8,MP_Jan.20!$G46) -> 2 | E17: =COUNTIF(MP_Jan.20!$F$9:$CT$9,MP_Jan.20!$G46) -> 3 | F17: =COUNTIF(MP_Jan.20!$F$10:$CT$10,MP_Jan.20!$G46) -> 1 | G17: =COUNTIF(MP_Jan.20!$F$11:$CT$11,MP_Jan.20!$G46) -> 4 | H17: =COUNTIF(MP_Jan.20!$F$12:$CT$12,MP_Jan.20!$G46) -> 10 | I17: Livre | J17: =COUNTIF(MP_Fev.20!$F$7:$CN$7,MP_Fev.20!$G46) -> 0 | K17: =COUNTIF(MP_Fev.20!$F$8:$CN$8,MP_Fev.20!$G46) -> 0 | L17: =COUNTIF(MP_Fev.20!$F$9:$CN$9,MP_Fev.20!$G46) -> 0 | M17: =COUNTIF(MP_Fev.20!$F$10:$CN$10,MP_Fev.20!$G46) -> 0 | N17: =COUNTIF(MP_Fev.20!$F$11:$CN$11,MP_Fev.20!$G46) -> 0 | O17: =COUNTIF(MP_Fev.20!$F$12:$CN$12,MP_Fev.20!$G46) -> 0 | P17: Livre | Q17: =COUNTIF(MP_Mar.20!$F$7:$CT$7,MP_Mar.20!$G46) -> 0 | R17: =COUNTIF(MP_Mar.20!$F$8:$CT$8,MP_Mar.20!$G46) -> 0 | S17: =COUNTIF(MP_Mar.20!$F$9:$CT$9,MP_Mar.20!$G46) -> 0 | T17: =COUNTIF(MP_Mar.20!$F$10:$CT$10,MP_Mar.20!$G46) -> 0 | U17: =COUNTIF(MP_Mar.20!$F$11:$CT$11,MP_Mar.20!$G46) -> 0 | V17: =COUNTIF(MP_Mar.20!$F$12:$CT$12,MP_Mar.20!$G46) -> 0 | W17: Livre | X17: =COUNTIF(MP_Abr.20!$F$7:$CQ$7,MP_Abr.20!$G46) -> 0 | Y17: =COUNTIF(MP_Abr.20!$F$8:$CQ$8,MP_Abr.20!$G46) -> 0 | Z17: =COUNTIF(MP_Abr.20!$F$9:$CQ$9,MP_Abr.20!$G46) -> 0 | AA17: =COUNTIF(MP_Abr.20!$F$10:$CQ$10,MP_Abr.20!$G46) -> 0 | AB17: =COUNTIF(MP_Abr.20!$F$11:$CQ$11,MP_Abr.20!$G46) -> 0 | AC17: =COUNTIF(MP_Abr.20!$F$12:$CQ$12,MP_Abr.20!$G46) -> 0 | AD17: Livre | AE17: =COUNTIF(MP_Mai.20!$F$7:$CT$7,MP_Mai.20!$G46) -> 0 | AF17: =COUNTIF(MP_Mai.20!$F$8:$CT$8,MP_Mai.20!$G46) -> 0 | AG17: =COUNTIF(MP_Mai.20!$F$9:$CT$9,MP_Mai.20!$G46) -> 0 | AH17: =COUNTIF(MP_Mai.20!$F$10:$CT$10,MP_Mai.20!$G46) -> 0 | AI17: =COUNTIF(MP_Mai.20!$F$11:$CT$11,MP_Mai.20!$G46) -> 0 | AJ17: =COUNTIF(MP_Mai.20!$F$12:$CT$12,MP_Mai.20!$G46) -> 0 | AK17: Livre | AL17: =COUNTIF(MP_Jun.20!$F$7:$CQ$7,MP_Jun.20!$G46) -> 0 | AM17: =COUNTIF(MP_Jun.20!$F$8:$CQ$8,MP_Jun.20!$G46) -> 0 | AN17: =COUNTIF(MP_Jun.20!$F$9:$CQ$9,MP_Jun.20!$G46) -> 0 | AO17: =COUNTIF(MP_Jun.20!$F$10:$CQ$10,MP_Jun.20!$G46) -> 0 | AP17: =COUNTIF(MP_Jun.20!$F$11:$CQ$11,MP_Jun.20!$G46) -> 0 | AQ17: =COUNTIF(MP_Jun.20!$F$12:$CQ$12,MP_Jun.20!$G46) -> 0 | AR17: Livre | AS17: =COUNTIF(MP_Jul.20!$F$7:$CT$7,MP_Jul.20!$G46) -> 0 | AT17: =COUNTIF(MP_Jul.20!$F$8:$CT$8,MP_Jul.20!$G46) -> 0 | AU17: =COUNTIF(MP_Jul.20!$F$9:$CT$9,MP_Jul.20!$G46) -> 0 | AV17: =COUNTIF(MP_Jul.20!$F$10:$CT$10,MP_Jul.20!$G46) -> 0 | AW17: =COUNTIF(MP_Jul.20!$F$11:$CT$11,MP_Jul.20!$G46) -> 0 | AX17: =COUNTIF(MP_Jul.20!$F$12:$CT$12,MP_Jul.20!$G46) -> 0 | AY17: Livre | AZ17: =COUNTIF(MP_Ago.20!$F$7:$CT$7,MP_Ago.20!$G46) -> 0 | BA17: =COUNTIF(MP_Ago.20!$F$8:$CT$8,MP_Ago.20!$G46) -> 0 | BB17: =COUNTIF(MP_Ago.20!$F$9:$CT$9,MP_Ago.20!$G46) -> 0 | BC17: =COUNTIF(MP_Ago.20!$F$10:$CT$10,MP_Ago.20!$G46) -> 0 | BD17: =COUNTIF(MP_Ago.20!$F$11:$CT$11,MP_Ago.20!$G46) -> 0 | BE17: =COUNTIF(MP_Ago.20!$F$12:$CT$12,MP_Ago.20!$G46) -> 0 | BF17: Livre | BG17: =COUNTIF(MP_Set.20!$F$7:$CQ$7,MP_Set.20!$G46) -> 0 | BH17: =COUNTIF(MP_Set.20!$F$8:$CQ$8,MP_Set.20!$G46) -> 0 | BI17: =COUNTIF(MP_Set.20!$F$9:$CQ$9,MP_Set.20!$G46) -> 0 | BJ17: =COUNTIF(MP_Set.20!$F$10:$CQ$10,MP_Set.20!$G46) -> 0 | BK17: =COUNTIF(MP_Set.20!$F$11:$CQ$11,MP_Set.20!$G46) -> 0 | BL17: =COUNTIF(MP_Set.20!$F$12:$CQ$12,MP_Set.20!$G46) -> 0 | BM17: Livre | BN17: =COUNTIF(MP_Out.20!$F$7:$CT$7,MP_Out.20!$G46) -> 0 | BO17: =COUNTIF(MP_Out.20!$F$8:$CT$8,MP_Out.20!$G46) -> 0 | BP17: =COUNTIF(MP_Out.20!$F$9:$CT$9,MP_Out.20!$G46) -> 0 | BQ17: =COUNTIF(MP_Out.20!$F$10:$CT$10,MP_Out.20!$G46) -> 0 | BR17: =COUNTIF(MP_Out.20!$F$11:$CT$11,MP_Out.20!$G46) -> 0 | BS17: =COUNTIF(MP_Out.20!$F$12:$CT$12,MP_Out.20!$G46) -> 0 | BT17: Livre | BU17: =COUNTIF(MP_Nov.20!$F$7:$CQ$7,MP_Nov.20!$G46) -> 0 | BV17: =COUNTIF(MP_Nov.20!$F$8:$CQ$8,MP_Nov.20!$G46) -> 0 | BW17: =COUNTIF(MP_Nov.20!$F$9:$CQ$9,MP_Nov.20!$G46) -> 0 | BX17: =COUNTIF(MP_Nov.20!$F$10:$CQ$10,MP_Nov.20!$G46) -> 0 | BY17: =COUNTIF(MP_Nov.20!$F$11:$CQ$11,MP_Nov.20!$G46) -> 0 | BZ17: =COUNTIF(MP_Nov.20!$F$12:$CQ$12,MP_Nov.20!$G46) -> 0 | CA17: Livre | CB17: =COUNTIF(MP_Dez.20!$F$7:$CT$7,MP_Dez.20!$G46) -> 0 | CC17: =COUNTIF(MP_Dez.20!$F$8:$CT$8,MP_Dez.20!$G46) -> 0 | CD17: =COUNTIF(MP_Dez.20!$F$9:$CT$9,MP_Dez.20!$G46) -> 0 | CE17: =COUNTIF(MP_Dez.20!$F$10:$CT$10,MP_Dez.20!$G46) -> 0 | CF17: =COUNTIF(MP_Dez.20!$F$11:$CT$11,MP_Dez.20!$G46) -> 0 | CG17: =COUNTIF(MP_Dez.20!$F$12:$CT$12,MP_Dez.20!$G46) -> 0
C18: =C6 -> HPLC.0034 | D18: =D6 -> HPLC.0035 | E18: =E6 -> HPLC.0036 | F18: =F6 -> HPLC.0037 | G18: =G6 -> HPLC.0045 | H18: =H6 -> HPLC.0050 | J18: =J6 -> HPLC.0034 | K18: =K6 -> HPLC.0035 | L18: =L6 -> HPLC.0036 | M18: =M6 -> HPLC.0037 | N18: =N6 -> HPLC.0045 | O18: =O6 -> HPLC.0050 | Q18: =Q6 -> HPLC.0034 | R18: =R6 -> HPLC.0035 | S18: =S6 -> HPLC.0036 | T18: =T6 -> HPLC.0037 | U18: =U6 -> HPLC.0045 | V18: =V6 -> HPLC.0050 | X18: =X6 -> HPLC.0034 | Y18: =Y6 -> HPLC.0035 | Z18: =Z6 -> HPLC.0036 | AA18: =AA6 -> HPLC.0037 | AB18: =AB6 -> HPLC.0045 | AC18: =AC6 -> HPLC.0050 | AE18: =AE6 -> HPLC.0034 | AF18: =AF6 -> HPLC.0035 | AG18: =AG6 -> HPLC.0036 | AH18: =AH6 -> HPLC.0037 | AI18: =AI6 -> HPLC.0045 | AJ18: =AJ6 -> HPLC.0050 | AL18: =AL6 -> HPLC.0034 | AM18: =AM6 -> HPLC.0035 | AN18: =AN6 -> HPLC.0036 | AO18: =AO6 -> HPLC.0037 | AP18: =AP6 -> HPLC.0045 | AQ18: =AQ6 -> HPLC.0050 | AS18: =AS6 -> HPLC.0034 | AT18: =AT6 -> HPLC.0035 | AU18: =AU6 -> HPLC.0036 | AV18: =AV6 -> HPLC.0037 | AW18: =AW6 -> HPLC.0045 | AX18: =AX6 -> HPLC.0050 | AZ18: =AZ6 -> HPLC.0034 | BA18: =BA6 -> HPLC.0035 | BB18: =BB6 -> HPLC.0036 | BC18: =BC6 -> HPLC.0037 | BD18: =BD6 -> HPLC.0045 | BE18: =BE6 -> HPLC.0050 | BG18: =BG6 -> HPLC.0034 | BH18: =BH6 -> HPLC.0035 | BI18: =BI6 -> HPLC.0036 | BJ18: =BJ6 -> HPLC.0037 | BK18: =BK6 -> HPLC.0045 | BL18: =BL6 -> HPLC.0050 | BN18: =BN6 -> HPLC.0034 | BO18: =BO6 -> HPLC.0035 | BP18: =BP6 -> HPLC.0036 | BQ18: =BQ6 -> HPLC.0037 | BR18: =BR6 -> HPLC.0045 | BS18: =BS6 -> HPLC.0050 | BU18: =BU6 -> HPLC.0034 | BV18: =BV6 -> HPLC.0035 | BW18: =BW6 -> HPLC.0036 | BX18: =BX6 -> HPLC.0037 | BY18: =BY6 -> HPLC.0045 | BZ18: =BZ6 -> HPLC.0050 | CB18: =CB6 -> HPLC.0034 | CC18: =CC6 -> HPLC.0035 | CD18: =CD6 -> HPLC.0036 | CE18: =CE6 -> HPLC.0037 | CF18: =CF6 -> HPLC.0045 | CG18: =CG6 -> HPLC.0050
B19: Dias em uso | C19: =SUM(C7:C8,C10:C15) -> 13 | D19: =SUM(D7:D8,D10:D15) -> 13 | E19: =SUM(E7:E8,E10:E15) -> 11 | F19: =SUM(F7:F8,F10:F15) -> 11 | G19: =SUM(G7:G8,G10:G15) -> 10 | H19: =SUM(H7:H8,H10:H15) -> 0 | I19: Dias em uso | J19: =SUM(J7:J8,J10:J15) -> 0 | K19: =SUM(K7:K8,K10:K15) -> 0 | L19: =SUM(L7:L8,L10:L15) -> 0 | M19: =SUM(M7:M8,M10:M15) -> 0 | N19: =SUM(N7:N8,N10:N15) -> 0 | O19: =SUM(O7:O8,O10:O15) -> 0 | P19: Dias em uso | Q19: =SUM(Q7:Q8,Q10:Q15) -> 0 | R19: =SUM(R7:R8,R10:R15) -> 0 | S19: =SUM(S7:S8,S10:S15) -> 0 | T19: =SUM(T7:T8,T10:T15) -> 0 | U19: =SUM(U7:U8,U10:U15) -> 0 | V19: =SUM(V7:V8,V10:V15) -> 0 | W19: Dias em uso | X19: =SUM(X7:X8,X10:X15) -> 0 | Y19: =SUM(Y7:Y8,Y10:Y15) -> 0 | Z19: =SUM(Z7:Z8,Z10:Z15) -> 0 | AA19: =SUM(AA7:AA8,AA10:AA15) -> 0 | AB19: =SUM(AB7:AB8,AB10:AB15) -> 0 | AC19: =SUM(AC7:AC8,AC10:AC15) -> 0 | AD19: Dias em uso | AE19: =SUM(AE7:AE8,AE10:AE15) -> 0 | AF19: =SUM(AF7:AF8,AF10:AF15) -> 0 | AG19: =SUM(AG7:AG8,AG10:AG15) -> 0 | AH19: =SUM(AH7:AH8,AH10:AH15) -> 0 | AI19: =SUM(AI7:AI8,AI10:AI15) -> 0 | AJ19: =SUM(AJ7:AJ8,AJ10:AJ15) -> 0 | AK19: Dias em uso | AL19: =SUM(AL7:AL8,AL10:AL15) -> 0 | AM19: =SUM(AM7:AM8,AM10:AM15) -> 0 | AN19: =SUM(AN7:AN8,AN10:AN15) -> 0 | AO19: =SUM(AO7:AO8,AO10:AO15) -> 0 | AP19: =SUM(AP7:AP8,AP10:AP15) -> 0 | AQ19: =SUM(AQ7:AQ8,AQ10:AQ15) -> 0 | AR19: Dias em uso | AS19: =SUM(AS7:AS8,AS10:AS15) -> 0 | AT19: =SUM(AT7:AT8,AT10:AT15) -> 0 | AU19: =SUM(AU7:AU8,AU10:AU15) -> 0 | AV19: =SUM(AV7:AV8,AV10:AV15) -> 0 | AW19: =SUM(AW7:AW8,AW10:AW15) -> 0 | AX19: =SUM(AX7:AX8,AX10:AX15) -> 0 | AY19: Dias em uso | AZ19: =SUM(AZ7:AZ8,AZ10:AZ15) -> 0 | BA19: =SUM(BA7:BA8,BA10:BA15) -> 0 | BB19: =SUM(BB7:BB8,BB10:BB15) -> 0 | BC19: =SUM(BC7:BC8,BC10:BC15) -> 0 | BD19: =SUM(BD7:BD8,BD10:BD15) -> 0 | BE19: =SUM(BE7:BE8,BE10:BE15) -> 0 | BF19: Dias em uso | BG19: =SUM(BG7:BG8,BG10:BG15) -> 0 | BH19: =SUM(BH7:BH8,BH10:BH15) -> 0 | BI19: =SUM(BI7:BI8,BI10:BI15) -> 0 | BJ19: =SUM(BJ7:BJ8,BJ10:BJ15) -> 0 | BK19: =SUM(BK7:BK8,BK10:BK15) -> 0 | BL19: =SUM(BL7:BL8,BL10:BL15) -> 0 | BM19: Dias em uso | BN19: =SUM(BN7:BN8,BN10:BN15) -> 0 | BO19: =SUM(BO7:BO8,BO10:BO15) -> 0 | BP19: =SUM(BP7:BP8,BP10:BP15) -> 0 | BQ19: =SUM(BQ7:BQ8,BQ10:BQ15) -> 0 | BR19: =SUM(BR7:BR8,BR10:BR15) -> 0 | BS19: =SUM(BS7:BS8,BS10:BS15) -> 0 | BT19: Dias em uso | BU19: =SUM(BU7:BU8,BU10:BU15) -> 0 | BV19: =SUM(BV7:BV8,BV10:BV15) -> 0 | BW19: =SUM(BW7:BW8,BW10:BW15) -> 0 | BX19: =SUM(BX7:BX8,BX10:BX15) -> 0 | BY19: =SUM(BY7:BY8,BY10:BY15) -> 0 | BZ19: =SUM(BZ7:BZ8,BZ10:BZ15) -> 0 | CA19: Dias em uso | CB19: =SUM(CB7:CB8,CB10:CB15) -> 0 | CC19: =SUM(CC7:CC8,CC10:CC15) -> 0 | CD19: =SUM(CD7:CD8,CD10:CD15) -> 0 | CE19: =SUM(CE7:CE8,CE10:CE15) -> 0 | CF19: =SUM(CF7:CF8,CF10:CF15) -> 0 | CG19: =SUM(CG7:CG8,CG10:CG15) -> 0
B20: Dias livre | C20: =SUM(C9,C16:C17) -> 2 | D20: =SUM(D9,D16:D17) -> 2 | E20: =SUM(E9,E16:E17) -> 3 | F20: =SUM(F9,F16:F17) -> 1 | G20: =SUM(G9,G16:G17) -> 4 | H20: =SUM(H9,H16:H17) -> 10 | I20: Dias livre | J20: =SUM(J9,J16:J17) -> 0 | K20: =SUM(K9,K16:K17) -> 0 | L20: =SUM(L9,L16:L17) -> 0 | M20: =SUM(M9,M16:M17) -> 0 | N20: =SUM(N9,N16:N17) -> 0 | O20: =SUM(O9,O16:O17) -> 0 | P20: Dias livre | Q20: =SUM(Q9,Q16:Q17) -> 0 | R20: =SUM(R9,R16:R17) -> 0 | S20: =SUM(S9,S16:S17) -> 0 | T20: =SUM(T9,T16:T17) -> 0 | U20: =SUM(U9,U16:U17) -> 0 | V20: =SUM(V9,V16:V17) -> 0 | W20: Dias livre | X20: =SUM(X9,X16:X17) -> 0 | Y20: =SUM(Y9,Y16:Y17) -> 0 | Z20: =SUM(Z9,Z16:Z17) -> 0 | AA20: =SUM(AA9,AA16:AA17) -> 0 | AB20: =SUM(AB9,AB16:AB17) -> 0 | AC20: =SUM(AC9,AC16:AC17) -> 0 | AD20: Dias livre | AE20: =SUM(AE9,AE16:AE17) -> 0 | AF20: =SUM(AF9,AF16:AF17) -> 0 | AG20: =SUM(AG9,AG16:AG17) -> 0 | AH20: =SUM(AH9,AH16:AH17) -> 0 | AI20: =SUM(AI9,AI16:AI17) -> 0 | AJ20: =SUM(AJ9,AJ16:AJ17) -> 0 | AK20: Dias livre | AL20: =SUM(AL9,AL16:AL17) -> 0 | AM20: =SUM(AM9,AM16:AM17) -> 0 | AN20: =SUM(AN9,AN16:AN17) -> 0 | AO20: =SUM(AO9,AO16:AO17) -> 0 | AP20: =SUM(AP9,AP16:AP17) -> 0 | AQ20: =SUM(AQ9,AQ16:AQ17) -> 0 | AR20: Dias livre | AS20: =SUM(AS9,AS16:AS17) -> 0 | AT20: =SUM(AT9,AT16:AT17) -> 0 | AU20: =SUM(AU9,AU16:AU17) -> 0 | AV20: =SUM(AV9,AV16:AV17) -> 0 | AW20: =SUM(AW9,AW16:AW17) -> 0 | AX20: =SUM(AX9,AX16:AX17) -> 0 | AY20: Dias livre | AZ20: =SUM(AZ9,AZ16:AZ17) -> 0 | BA20: =SUM(BA9,BA16:BA17) -> 0 | BB20: =SUM(BB9,BB16:BB17) -> 0 | BC20: =SUM(BC9,BC16:BC17) -> 0 | BD20: =SUM(BD9,BD16:BD17) -> 0 | BE20: =SUM(BE9,BE16:BE17) -> 0 | BF20: Dias livre | BG20: =SUM(BG9,BG16:BG17) -> 0 | BH20: =SUM(BH9,BH16:BH17) -> 0 | BI20: =SUM(BI9,BI16:BI17) -> 0 | BJ20: =SUM(BJ9,BJ16:BJ17) -> 0 | BK20: =SUM(BK9,BK16:BK17) -> 0 | BL20: =SUM(BL9,BL16:BL17) -> 0 | BM20: Dias livre | BN20: =SUM(BN9,BN16:BN17) -> 0 | BO20: =SUM(BO9,BO16:BO17) -> 0 | BP20: =SUM(BP9,BP16:BP17) -> 0 | BQ20: =SUM(BQ9,BQ16:BQ17) -> 0 | BR20: =SUM(BR9,BR16:BR17) -> 0 | BS20: =SUM(BS9,BS16:BS17) -> 0 | BT20: Dias livre | BU20: =SUM(BU9,BU16:BU17) -> 0 | BV20: =SUM(BV9,BV16:BV17) -> 0 | BW20: =SUM(BW9,BW16:BW17) -> 0 | BX20: =SUM(BX9,BX16:BX17) -> 0 | BY20: =SUM(BY9,BY16:BY17) -> 0 | BZ20: =SUM(BZ9,BZ16:BZ17) -> 0 | CA20: Dias livre | CB20: =SUM(CB9,CB16:CB17) -> 0 | CC20: =SUM(CC9,CC16:CC17) -> 0 | CD20: =SUM(CD9,CD16:CD17) -> 0 | CE20: =SUM(CE9,CE16:CE17) -> 0 | CF20: =SUM(CF9,CF16:CF17) -> 0 | CG20: =SUM(CG9,CG16:CG17) -> 0
B22: HPLC.0034 | D22: HPLC.0035 | F22: HPLC.0036 | H22: HPLC.0037 | J22: HPLC.0045 | L22: HPLC.0050
